Workbook
Name AUMENTO: 'GASTOS ADMINISTRATIVOS'!#REF!
Name FACT: 'COMEDORES VALLE'!#REF!
Name INCREMENTO: 'GASTOS ADMINISTRATIVOS'!#REF!
Name Total_Acqui: #REF!
Name Total_Bogotá: #REF!
Name Total_Pari: #REF!
Name AUMENTO: 'GASTOS ADMINISTRATIVOS'!#REF!
Name FACT: 'COMEDORES VALLE'!#REF!
Name INCREMENTO: 'GASTOS ADMINISTRATIVOS'!#REF!
Name AUMENTO: 'GASTOS ADMINISTRATIVOS'!#REF!
Name FACT: 'COMEDORES VALLE'!#REF!
Name INCREMENTO: 'GASTOS ADMINISTRATIVOS'!#REF!

Sheet %DIST
A1: DISTRIBUCION PERSONAL OPERATIVO
E2: =E5/2 | G2: =G5/2 | I2: =I5/2 | K2: =K5/2 | M2: =M5/2 | O2: =O5/2 | Q2: =Q5/2 | S2: =S5/2 | U2: =U5/2 | W2: =W5/2
B3: ENE | C3: % | D3: FEB | E3: % | F3: MAR | G3: % | H3: ABR | I3: % | J3: MAY | K3: % | L3: JUN | M3: % | N3: JUL | O3: % | P3: AGO | Q3: % | R3: SEP | S3: % | T3: OCT | U3: % | V3: NOV | W3: % | X3: DIC | Y3: %
A4: CALI | C4: 0.15802632 | E4: 0.35073589 | F4: =CALI!I$12 | G4: =F4/F$14 | H4: =CALI!L$12 | I4: =H4/H$14 | J4: =CALI!O$12 | K4: =J4/J$14 | L4: =CALI!R$12 | M4: =L4/L$14 | N4: =CALI!U$12 | O4: =N4/N$14 | P4: =CALI!X$12 | Q4: =P4/P$14 | R4: =CALI!AA$12 | S4: =R4/R$14 | T4: =CALI!AD$12 | U4: =T4/T$14 | V4: =CALI!AG$12 | W4: =V4/V$14 | X4: =CALI!AJ$12 | Y4: =X4/X$14 | Z4: 0.082331474
A5: YUMBO | C5: 0.092315605 | E5: 0.21581822 | F5: =YUMBO!I$12 | G5: =F5/F$14 | H5: =YUMBO!L$12 | I5: =H5/H$14 | J5: =YUMBO!O$12 | K5: =J5/J$14 | L5: =YUMBO!R$12 | M5: =L5/L$14 | N5: =YUMBO!U$12 | O5: =N5/N$14 | P5: =YUMBO!X$12 | Q5: =P5/P$14 | R5: =YUMBO!AA$12 | S5: =R5/R$14 | T5: =YUMBO!AD$12 | U5: =T5/T$14 | V5: =YUMBO!AG$12 | W5: =V5/V$14 | X5: =YUMBO!AJ$12 | Y5: =X5/X$14 | Z5: 0.15465757
A6: GOBERNACION | C6: 0 | E6: 0 | G6: =F6/F$14 | I6: =H6/H$14 | K6: =J6/J$14 | M6: =L6/L$14 | O6: =N6/N$14 | Q6: =P6/P$14 | S6: =R6/R$14 | U6: =T6/T$14 | W6: =V6/V$14 | Y6: =X6/X$14 | Z6: 0
A7: BUGA | C7: 0 | E7: 0 | G7: =F7/F$14 | I7: =H7/H$14 | K7: =J7/J$14 | M7: =L7/L$14 | O7: =N7/N$14 | Q7: =P7/P$14 | S7: =R7/R$14 | U7: =T7/T$14 | W7: =V7/V$14 | Y7: =X7/X$14 | Z7: 0
A8: HUNGRIA | C8: 0 | E8: 0 | F8: =HUNGRIA!I$12 | G8: =F8/F$14 | H8: =HUNGRIA!L$5 | I8: =H8/H$14 | J8: =HUNGRIA!O$5 | K8: =J8/J$14 | L8: =HUNGRIA!R$12 | M8: =L8/L$14 | N8: =HUNGRIA!U$12 | O8: =N8/N$14 | P8: =HUNGRIA!X$12 | Q8: =P8/P$14 | R8: =HUNGRIA!AA$12 | S8: =R8/R$14 | T8: =HUNGRIA!AD$12 | U8: =T8/T$14 | V8: =HUNGRIA!AG$12 | W8: =V8/V$14 | X8: =HUNGRIA!AJ$12 | Y8: =X8/X$14
A9: COMEDORES CALI | C9: 0.7275737 | E9: 0.42310873 | F9: ='COMEDORES CALI'!$I$12 | G9: =F9/F$14 | H9: ='COMEDORES CALI'!$L$12 | I9: =H9/H$14 | J9: ='COMEDORES CALI'!O$12 | K9: =J9/J$14 | L9: ='COMEDORES CALI'!R$12 | M9: =L9/L$14 | N9: ='COMEDORES CALI'!U$12 | O9: =N9/N$14 | P9: ='COMEDORES CALI'!X$12 | Q9: =P9/P$14 | R9: ='COMEDORES CALI'!AA$12 | S9: =R9/R$14 | T9: ='COMEDORES CALI'!AD$12 | U9: =T9/T$14 | V9: ='COMEDORES CALI'!AG$12 | W9: =V9/V$14 | X9: ='COMEDORES CALI'!AJ$12 | Y9: =X9/X$14 | Z9: 0.02828364
A10: COMEDORES GOB | G10: =F10/F$14 | I10: =H10/H$14 | K10: =J10/J$14 | M10: =L10/L$14 | O10: =N10/N$14 | Q10: =P10/P$14 | S10: =R10/R$14 | U10: =T10/T$14 | W10: =V10/V$14 | Y10: =X10/X$14 | Z10: 0.0012929073
A11: COMEDORES PALMIRA | C11: 0.022084378 | E11: 0.010337164 | F11: ='COMEDORES PALMIRA'!I$12 | G11: =F11/F$14 | H11: ='COMEDORES PALMIRA'!L$12 | I11: =H11/H$14 | J11: ='COMEDORES PALMIRA'!O$12 | K11: =J11/J$14 | L11: ='COMEDORES PALMIRA'!R$12 | M11: =L11/L$14 | N11: ='COMEDORES PALMIRA'!U$12 | O11: =N11/N$14 | P11: ='COMEDORES PALMIRA'!X$12 | Q11: =P11/P$14 | R11: ='COMEDORES PALMIRA'!AA$12 | S11: =R11/R$14 | T11: ='COMEDORES PALMIRA'!AD$12 | U11: =T11/T$14 | V11: ='COMEDORES PALMIRA'!$AG$12 | W11: =V11/V$14 | X11: ='COMEDORES PALMIRA'!$AJ$12 | Y11: =X11/X$14 | Z11: 0.029041283
A12: ADULTO MAYOR | C12: 0 | E12: 0 | F12: ='ADULTO MAYOR'!I$12*20 | G12: =F12/F$14 | H12: ='ADULTO MAYOR'!L$12*20 | I12: =H12/H$14 | J12: ='ADULTO MAYOR'!O$12*20 | K12: =J12/J$14 | L12: ='ADULTO MAYOR'!R$12*20 | M12: =L12/L$14 | N12: ='ADULTO MAYOR'!U$12*20 | O12: =N12/N$14 | P12: ='ADULTO MAYOR'!X$12*20 | Q12: =P12/P$14 | R12: ='ADULTO MAYOR'!AA$12*20 | S12: =R12/R$14 | T12: ='ADULTO MAYOR'!AD$12*20 | U12: =T12/T$14 | V12: ='ADULTO MAYOR'!AG$12*20 | W12: =V12/V$14 | X12: ='ADULTO MAYOR'!AJ$12*20 | Y12: =X12/X$14 | Z12: 0.67336335
A13: IMDERTY | C13: 0 | E13: 0 | F13: =IMDERTY!I$12 | G13: =F13/F$14 | H13: =IMDERTY!L$12 | I13: =H13/H$14 | J13: =IMDERTY!O$12 | K13: =J13/J$14 | L13: =IMDERTY!R$12 | M13: =L13/L$14 | N13: =IMDERTY!$U$12 | O13: =N13/N$14 | P13: =IMDERTY!X$12 | Q13: =P13/P$14 | R13: =IMDERTY!AA$12 | S13: =R13/R$14 | T13: =IMDERTY!AD$12 | U13: =T13/T$14 | V13: =IMDERTY!AG$12 | W13: =V13/V$14 | X13: =IMDERTY!AJ$12 | Y13: =X13/X$14 | Z13: 0.031029775
B14: =SUM(B4:B13) | C14: =SUM(C4:C13) | D14: =SUM(D4:D13) | E14: =SUM(E4:E13) | F14: =SUM(F4:F13) | G14: =SUM(G4:G13) | H14: =SUM(H4:H13) | I14: =SUM(I4:I13) | ... Y14: =SUM(Y4:Y13)
A17: DISTRIBUCION FLETES INTERNOS
B19: ENE | D19: FEB | F19: MAR | H19: ABR | J19: MAY | L19: JUN | N19: JUL | P19: AGO | R19: SEP | T19: OCT | V19: NOV | X19: DIC
A20: CALI | B20: 0.22 | D20: 0.685 | F20: 0.64 | H20: 0.565 | J20: 0.47 | L20: 0.6 | N20: 0.23 | P20: 0.495 | R20: 0.53 | T20: 0.38 | V20: 0.52 | AA20: 0.2
A21: YUMBO | B21: 0.075 | D21: 0.2 | F21: 0.18 | H21: 0.19 | J21: 0.19 | L21: 0.09 | N21: 0.13 | P21: 0.175 | R21: 0.16 | T21: 0.12 | V21: 0.2
A22: GOBERNACION
A23: BUGA | B23: 0.015 | D23: 0.02 | F23: 0.02 | H23: 0.035 | J23: 0.04 | L23: 0.02 | N23: 0.01 | P23: 0.015 | R23: 0.01 | T23: 0.02 | V23: 0.01 | AA23: 0.15
A24: HUNGRIA | AA24: 0.55
A25: COMEDORES CALI | B25: 0.67 | D25: 0.085 | F25: 0.16 | H25: 0.175 | J25: 0.1 | L25: 0.09 | N25: 0.32 | P25: 0.115 | R25: 0.13 | T25: 0.21 | V25: 0.09 | X25: 0.89
A26: COMEDORES GOB | J26: 0.17 | L26: 0.15 | N26: 0.25 | P26: 0.15 | R26: 0.13 | T26: 0.15 | V26: 0.15 | AA26: 0.04
A27: COMEDORES PALMIRA | B27: 0.02 | D27: 0.01 | N27: 0.01 | P27: 0.005 | R27: 0.03 | T27: 0.04 | V27: 0.03 | X27: 0.11
A28: ADULTO MAYOR | H28: 0.035 | J28: 0.03 | L28: 0.05 | N28: 0.05 | P28: 0.045 | R28: 0.01 | T28: 0.08
A29: IMDERTY
B30: =SUM(B20:B29) | D30: =SUM(D20:D29) | F30: =SUM(F20:F29) | H30: =SUM(H20:H29) | J30: =SUM(J20:J29) | L30: =SUM(L20:L29) | N30: =SUM(N20:N29) | P30: =SUM(P20:P29) | R30: =SUM(R20:R29) | T30: =SUM(T20:T29) | V30: =SUM(V20:V29) | X30: =SUM(X20:X29)
A33: DISTRIBUCION PERSONAL ADMINISTRATIVO
B35: ENE | D35: FEB | F35: MAR | H35: ABR | J35: MAY | L35: JUN | N35: JUL | P35: AGO | R35: SEP | T35: OCT | V35: NOV | X35: DIC
A36: CALI | B36: =C52 | D36: =E52 | F36: =G52 | H36: =I52 | J36: =K52 | L36: =M52 | N36: =O52 | P36: =Q52 | R36: =S52 | T36: =U52 | V36: =W52 | X36: =Y52
A37: YUMBO | B37: =C53 | D37: =E53 | F37: =G53 | H37: =I53 | J37: =K53 | L37: =M53 | N37: =O53 | P37: =Q53 | R37: =S53 | T37: =U53 | V37: =W53 | X37: =Y53
A38: GOBERNACION | B38: =C54 | D38: =E54 | F38: =G54 | H38: =I54 | J38: =K54 | L38: =M54 | N38: =O54 | P38: =Q54 | R38: =S54 | T38: =U54 | V38: =W54 | X38: =Y54
A39: BUGA | B39: =C55 | D39: =E55 | F39: =G55 | H39: =I55 | J39: =K55 | L39: =M55 | N39: =O55 | P39: =Q55 | R39: =S55 | T39: =U55 | V39: =W55 | X39: =Y55
A40: HUNGRIA | B40: =C56 | D40: =E56 | F40: =G56 | H40: =I56 | J40: =K56 | L40: =M56 | N40: =O56 | P40: =Q56 | R40: =S56 | T40: =U56 | V40: =W56 | X40: =Y56
A41: COMEDORES CALI | B41: =C57-B45 | D41: =E57-D45 | F41: =G57-F45 | H41: =I57-H45 | J41: =K57-J45 | L41: =M57-L45 | N41: =O57-N45 | P41: =Q57-P45 | R41: =S57-R45 | T41: =U57-T45 | V41: =W57-V45 | X41: =Y57-X45
A42: COMEDORES GOB | B42: =C58 | D42: =E58 | F42: =G58 | H42: =I58 | J42: =K58 | L42: =M58 | N42: =O58 | P42: =Q58 | R42: =S58 | T42: =U58 | V42: =W58 | X42: =Y58
A43: COMEDORES PALMIRA | B43: =C59 | D43: =E59 | F43: =G59 | H43: =I59 | J43: =K59 | L43: =M59 | N43: =O59 | P43: =Q59 | R43: =S59 | T43: =U59 | V43: =W59 | X43: =Y59
A44: ADULTO MAYOR | B44: =C60 | D44: =E60 | F44: =G60 | H44: =I60 | J44: =K60 | L44: =M60 | N44: =O60 | P44: =Q60 | R44: =S60 | T44: =U60 | V44: =W60 | X44: =Y60
A45: CTAS PPACION | B45: 0.01 | D45: 0.01 | F45: 0.01 | H45: 0.01 | J45: 0.01 | L45: 0.01 | N45: 0.01 | P45: 0.01 | R45: 0.01 | T45: 0.01 | V45: 0.01 | X45: 0.01
B46: =SUM(B36:B45) | D46: =SUM(D36:D45) | F46: =SUM(F36:F45) | H46: =SUM(H36:H45) | J46: =SUM(J36:J45) | L46: =SUM(L36:L45) | N46: =SUM(N36:N45) | P46: =SUM(P36:P45) | R46: =SUM(R36:R45) | T46: =SUM(T36:T45) | V46: =SUM(V36:V45) | X46: =SUM(X36:X45)
...

Sheet GASTOS ADMINISTRATIVOS
B2: CORPORACIÓN HACIA UN VALLE SOLIDARIO | C2: GASTOS ADMINISTRATIVOS 2026
C4: ENE | D4: FEB | E4: MAR | F4: ABR | G4: MAY | H4: JUN | I4: JUL | J4: AGO | K4: SEP | L4: OCT | M4: NOV | N4: DIC | O4: ACUMULADO
B5: GASTOS DE PERSONAL | C5: =SUM(C6:C12) | D5: =SUM(D6:D12) | E5: =SUM(E6:E12) | F5: =SUM(F6:F12) | G5: =SUM(G6:G12) | H5: =SUM(H6:H12) | I5: =SUM(I6:I12) | J5: =SUM(J6:J12) | ... O5: =SUM(O6:O12)
A6: 5105 | B6: Salarios | C6: ='[1]Hoja 1'!$I$9-921014+'[2]Hoja 1'!$I$9+'[3]Hoja 1'!$D$8 | D6: ='[4]Hoja 1'!$L$8-6457629+'[5]Hoja 1'!$I$9+'[6]Hoja 1'!$D$8+'[7]Hoja 1'!$D$10+'[8]Hoja 1'!$I$9 | E6: 241842440 | O6: =+SUM(C6:N6)
B7: Personal Decreto 1860/21 | C7: ='[1]Hoja 1'!$I$12 | D7: ='[4]Hoja 1'!$L$10 | E7: 241842440 | O7: =+SUM(C7:N7)
A8: 51055101 | B8: Dotacion y Suministro | C8: ='[9]Hoja 1'!$C$54-225638 | D8: ='[10]Hoja 1'!$C$54-59862 | E8: 241842440 | O8: =+SUM(C8:N8)
B9: Bonificaciones | E9: 241842440 | O9: =+SUM(C9:N9)
A10: 51056301 | B10: Capacitacion | C10: ='[9]Hoja 1'!$C$56 | D10: ='[10]Hoja 1'!$C$56 | E10: 241842440 | O10: =+SUM(C10:N10)
A11: 51058401 | B11: Gastos Medicos | C11: ='[9]Hoja 1'!$C$70 | D11: ='[10]Hoja 1'!$C$70 | E11: 241842440 | O11: =+SUM(C11:N11)
A12: 53954002 | B12: Incapacidades | D12: ='[11]Hoja 1'!$C$27 | E12: 241842440 | O12: =+SUM(C12:N12)
B13: HONORARIOS | C13: =SUM(C14:C18) | D13: =SUM(D14:D18) | E13: =SUM(E14:E18) | F13: =SUM(F14:F18) | G13: =SUM(G14:G18) | H13: =SUM(H14:H18) | I13: =SUM(I14:I18) | J13: =SUM(J14:J18) | ... O13: =SUM(O14:O18)
A14: 51101001 | B14: Revisoria Fiscal | C14: ='[9]Hoja 1'!$C$73 | D14: ='[10]Hoja 1'!$C$73 | E14: 241842440 | O14: =+SUM(C14:N14)
B15: Avaluos | E15: 241842440 | O15: =+SUM(C15:N15)
A16: 51102001 | B16: Asesoria Juridica | C16: ='[9]Hoja 1'!$C$75+'[12]Hoja 1'!$G$13 | D16: ='[10]Hoja 1'!$C$75+'[13]Hoja 1'!$G$14 | E16: 241842440 | O16: =+SUM(C16:N16)
A17: 51103001 | B17: Asesoria Financiera | E17: 241842440 | O17: =+SUM(C17:N17)
A18: 51103508 | B18: Asesoría Técnica | C18: ='[9]Hoja 1'!$C$77 | D18: ='[10]Hoja 1'!$C$76 | E18: 241842440 | O18: =+SUM(C18:N18)
B19: IMPUESTOS | C19: =SUM(C20:C21) | D19: =SUM(D20:D21) | E19: =SUM(E20:E21) | F19: =SUM(F20:F21) | G19: =SUM(G20:G21) | H19: =SUM(H20:H21) | I19: =SUM(I20:I21) | J19: =SUM(J20:J21) | ... O19: =SUM(O20:O21)
B20: Predial | E20: 241842440 | O20: =+SUM(C20:N20)
B21: Impuestos vehiculos | C21: 2676712 | E21: 241842440 | O21: =+SUM(C21:N21)
B22: ARRENDAMIENTOS | C22: =SUM(C23:C27) | D22: =SUM(D23:D27) | E22: =SUM(E23:E27) | F22: =SUM(F23:F27) | G22: =SUM(G23:G27) | H22: =SUM(H23:H27) | I22: =SUM(I23:I27) | J22: =SUM(J23:J27) | ... O22: =SUM(O23:O27)
A23: 51201001 - 51355001 | B23: Construcciones y Edificaciones | C23: ='[9]Hoja 1'!$C$85+'[12]Hoja 1'!$G$15+'[12]Hoja 1'!$G$17 | D23: ='[10]Hoja 1'!$C$84+'[13]Hoja 1'!$G$16+'[13]Hoja 1'!$G$18 | E23: 241842440 | O23: =+SUM(C23:N23)
A24: 51201501 - 73201501 | B24: Maquinaria y Equipo | C24: ='[9]Hoja 1'!$C$87 | D24: ='[10]Hoja 1'!$C$86 | E24: 241842440 | O24: =+SUM(C24:N24)
A25: 51202001 | B25: Equipo de Oficina | C25: ='[9]Hoja 1'!$C$89 | D25: ='[10]Hoja 1'!$C$88 | E25: 241842440 | O25: =+SUM(C25:N25)
B26: Equipo de Computacion y comunicaciones | D26: ='[10]Hoja 1'!$C$90 | E26: 241842440 | O26: =+SUM(C26:N26)
B27: Flota y Equipo de Transporte | E27: 241842440 | O27: =+SUM(C27:N27)
B28: SEGUROS | C28: =SUM(C29:C31) | D28: =SUM(D29:D31) | E28: =SUM(E29:E31) | F28: =SUM(F29:F31) | G28: =SUM(G29:G31) | H28: =SUM(H29:H31) | I28: =SUM(I29:I31) | J28: =SUM(J29:J31) | ... O28: =SUM(O29:O31)
B29: Cumplimiento | E29: 241842440 | O29: =+SUM(C29:N29)
B30: Responsabilidad Civil y Extracontractual | E30: 241842440 | O30: =+SUM(C30:N30)
B31: OTROS - Funerarios | D31: ='[10]Hoja 1'!$C$95 | E31: 241842440 | O31: =+SUM(C31:N31)
B32: SERVICIOS | C32: =SUM(C33:C45) | D32: =SUM(D33:D45) | E32: =SUM(E33:E45) | F32: =SUM(F33:F45) | G32: =SUM(G33:G45) | H32: =SUM(H33:H45) | I32: =SUM(I33:I45) | J32: =SUM(J33:J45) | ... O32: =SUM(O33:O45)
B33: Aseo y Vigilancia | C33: ='[12]Hoja 1'!$G$22 | D33: ='[13]Hoja 1'!$G$23 | E33: 241842440 | O33: =+SUM(C33:N33)
A34: 51351001 - 51351004 | B34: Temporales | C34: ='[9]Hoja 1'!$C$97 | D34: ='[10]Hoja 1'!$C$99 | E34: 241842440 | O34: =+SUM(C34:N34)
B35: Comunicaciones | E35: 241842440 | O35: =+SUM(C35:N35)
A36: 51351502 | B36: Laboratorio | D36: ='[10]Hoja 1'!C103 | E36: 241842440 | O36: =+SUM(C36:N36)
A37: 51351503 | B37: Fumigacion | C37: ='[9]Hoja 1'!$C$99 | D37: ='[10]Hoja 1'!C104 | E37: 241842440 | O37: =+SUM(C37:N37)
A38: 51352501 | B38: Acueducto y Alcantarillado | C38: ='[9]Hoja 1'!$C$101 | D38: ='[10]Hoja 1'!$C$106 | E38: 241842440 | O38: =+SUM(C38:N38)
A39: 51353001 | B39: Energía Electrica | C39: ='[9]Hoja 1'!$C$103 | D39: ='[10]Hoja 1'!$C$108 | E39: 241842440 | O39: =+SUM(C39:N39)
A40: 51353501 | B40: Telefono | C40: ='[9]Hoja 1'!C105 | D40: ='[10]Hoja 1'!C110-98250 | E40: 241842440 | O40: =+SUM(C40:N40)
A41: 51353502 | B41: Internet | C41: ='[9]Hoja 1'!C106 | D41: ='[10]Hoja 1'!C111 | E41: 241842440 | O41: =+SUM(C41:N41)
A42: 51354001 | B42: Correo, Portes, telegramas | C42: ='[9]Hoja 1'!$C$108 | D42: ='[10]Hoja 1'!$C$113 | E42: 241842440 | O42: =+SUM(C42:N42)
...

Sheet GASTOS OPERATIVOS
B2: CORPORACIÓN HACIA UN VALLE SOLIDARIO | C2: 242070540
C4: ENE | D4: FEB | E4: MAR | F4: ABR | G4: MAY | H4: JUN | I4: JUL | J4: AGO | K4: SEP | L4: OCT | M4: NOV | N4: DIC | O4: ACUMULADO
B5: GASTOS DE PERSONAL | C5: =SUM(C6:C10) | D5: =SUM(D6:D10) | G5: =SUM(G6:G10) | H5: =SUM(H6:H10) | I5: =SUM(I6:I10) | J5: =SUM(J6:J10) | K5: =SUM(K6:K10) | L5: =SUM(L6:L10) | M5: =SUM(M6:M10) | N5: =SUM(N6:N10) | O5: =SUM(O6:O10)
A6: 7205 | B6: Salarios | C6: ='[21]Hoja 1'!$I$8-C9+'[22]Hoja 1'!$I$9+'[23]Hoja 1'!$D$9+'[24]Hoja 1'!$D$9+'[25]Hoja 1'!$C$91+'[26]Hoja 1'!$D$9+'[27]Hoja 1'!$E$9+'[28]Hoja 1'!$E$10 | D6: ='[29]Hoja 1'!$I$8+'[30]Hoja 1'!$I$8-D9+'[31]Hoja 1'!$I$9+'[32]Hoja 1'!$D$9+'[33]Hoja 1'!$D$9+'[34]Hoja 1'!$D$9+'[35]Hoja 1'!$I$9 | E6: 55134543 | O6: =SUM(C6:N6)
B7: Casos Especiales | C7: ='[21]Hoja 1'!$I$9+'[23]Hoja 1'!$D$10 | D7: ='[29]Hoja 1'!$I$9+'[29]Hoja 1'!$D$32+'[32]Hoja 1'!$D$10+'[36]Hoja 1'!$D$10 | E7: 241842440 | O7: =SUM(C7:N7)
B8: Incapacidades Especiales | E8: 241842440 | O8: =SUM(C8:N8)
A9: 72055101 | B9: Dotacion y Suministro | C9: ='[9]Hoja 1'!$C$218 | D9: ='[18]Hoja 1'!$C$76+'[20]Hoja 1'!$C$81-152082 | E9: 23992227 | O9: =SUM(C9:N9)
A10: 72058401 | B10: Gastos Medicos | D10: ='[10]Hoja 1'!$C$239 | E10: 23992227 | O10: =SUM(C10:N10)
B11: CUOTA DE APOYO Y SOSTENIMIENTO | E11: 23734730 | K11: 0
B12: DIVERSOS | C12: =SUM(C13:C16) | D12: =SUM(D13:D16) | G12: =SUM(G13:G16) | H12: =SUM(H13:H16) | I12: =SUM(I13:I16) | J12: =SUM(J13:J16) | K12: =SUM(K13:K16) | L12: =SUM(L13:L16) | M12: =SUM(M13:M16) | N12: =SUM(N13:N16) | O12: =SUM(O13:O16)
A13: 71101001 - 73952501 | B13: Aseo | C13: ='[9]Hoja 1'!$C$196+'[9]Hoja 1'!$C$234 | D13: ='[10]Hoja 1'!$C$201+'[10]Hoja 1'!$C$243 | E13: 23734730 | O13: =SUM(C13:N13)
A14: 73959504 | B14: Averias | C14: ='[9]Hoja 1'!$C$236 | D14: ='[10]Hoja 1'!$C$245 | O14: =SUM(C14:N14)
B15: Equipos de Bodega | E15: 23734730 | O15: =SUM(C15:N15)
A16: 51959509 - 71102001 | B16: Bioseguridad + EPP | C16: ='[9]Hoja 1'!$C$198 | D16: ='[10]Hoja 1'!$C$158+'[10]Hoja 1'!$C$203 | E16: 4115810 | O16: =SUM(C16:N16)
B17: TOTAL GASTOS | C17: =C5+C11+C12 | D17: =D5+D11+D12 | G17: =G5+G11+G12 | H17: =H5+H11+H12 | I17: =I5+I11+I12 | J17: =J5+J11+J12 | K17: =K5+K11+K12 | L17: =L5+L11+L12 | M17: =M5+M11+M12 | N17: =N5+N11+N12 | O17: =O5+O11+O12
C20: 83159889 | D20: 148056842 | E20: 166932975 | F20: 194850261 | G20: 219335066 | I20: 177744901 | J20: 217896905 | K20: 262294276 | L20: 262819240 | M20: 251102591 | N20: 223519101 | O20: =SUM(C20:N20)
C21: =C6-C20 | D21: =D6-D20 | E21: =E6-E20 | F21: =F6-F20 | G21: =G6-G20 | I21: =I6-I20 | J21: =J6-J20 | K21: =K6-K20 | L21: =L6-L20 | M21: =M6-M20 | N21: =N6-N20 | O21: =SUM(C21:N21)
C22: =C21/C20 | D22: =D21/D20 | E22: =E21/E20 | F22: =F21/F20 | G22: =G21/G20 | I22: =I21/I20 | J22: =J21/J20 | K22: =K21/K20 | L22: =L21/L20 | M22: =M21/M20 | N22: =N21/N20 | O22: =O21/O20
K25: =K20-J20 | L25: dif ago y sep 2024
K27: =K25*8 | L27: dif * 8 meses
K28: =K27+O20 | L28: 2024+dif
K29: =K28*11% | L29: incremento 11%
K30: =K28+K29 | L30: incr + 2024
K31: 535655289 | L31: 17 personas
K32: =K30+K31 | L32: 17 p +inc +2024
K33: =O6-K32 | L33: dif 2024 vs ppto
K34: =8%*K6*12 | L34: bonificacion 2025
K35: =K33-K34 | L35: dif + bonificacion

Sheet GASTOS VEHICULOS
B2: CORPORACIÓN HACIA UN VALLE SOLIDARIO | C2: PRESUPUESTO GASTOS VEHICULOS 2026
C4: ENE | D4: FEB | E4: MAR | F4: ABR | G4: MAY | H4: JUN | I4: JUL | J4: AGO | K4: SEP | L4: OCT | M4: NOV | N4: DIC | O4: ACUMULADO
B5: GASTOS DE PERSONAL | C5: =SUM(C6:C8) | D5: =SUM(D6:D8) | E5: =SUM(E6:E8) | F5: =SUM(F6:F8) | G5: =SUM(G6:G8) | H5: =SUM(H6:H8) | I5: =SUM(I6:I8) | J5: =SUM(J6:J8) | ... O5: =SUM(O6:O8)
A6: 7205 | B6: Salarios | C6: ='[22]Hoja 1'!$I$10+'[27]Hoja 1'!$E$10 | D6: ='[30]Hoja 1'!$I$9+'[31]Hoja 1'!$I$10+'[35]Hoja 1'!$I$10-D7 | O6: =SUM(C6:N6)
A7: 72055101 | B7: Dotacion | D7: 152082 | O7: =SUM(C7:N7)
B8: Gastos Medicos | O8: =SUM(C8:N8)
B9: IMPUESTOS | C9: =SUM(C10) | D9: =SUM(D10) | G9: =SUM(G10) | H9: =SUM(H10) | I9: =SUM(I10) | J9: =SUM(J10) | K9: =SUM(K10) | L9: =SUM(L10) | M9: =SUM(M10) | N9: =SUM(N10) | O9: =SUM(O10)
B10: Impuestos Vehiculo | C10: ='[9]Hoja 1'!$C$80-2676712 | E10: 241842440 | O10: =SUM(C10:N10)
B11: SEGUROS | C11: =SUM(C12:C14) | D11: =SUM(D12:D14) | G11: =SUM(G12:G14) | H11: =SUM(H12:H14) | I11: =SUM(I12:I14) | J11: =SUM(J12:J14) | K11: =SUM(K12:K14) | L11: =SUM(L12:L14) | M11: =SUM(M12:M14) | N11: =SUM(N12:N14) | O11: =SUM(O12:O14)
A12: 51303501 | B12: Sustraccion y Hurto | E12: 241842440 | O12: =SUM(C12:N12)
A13: 51304001 | B13: Flota y Equipo de Transporte | D13: ='[10]Hoja 1'!$C$93 | E13: 241842440 | O13: =SUM(C13:N13)
B14: Obligatorio Accidente de transito | C14: ='[9]Hoja 1'!$C$92 | E14: 241842440 | O14: =SUM(C14:N14)
B15: SERVICIOS | C15: =SUM(C16:C18) | D15: =SUM(D16:D18) | G15: =SUM(G16:G18) | H15: =SUM(H16:H18) | I15: =SUM(I16:I18) | J15: =SUM(J16:J18) | K15: =SUM(K16:K18) | L15: =SUM(L16:L18) | M15: =SUM(M16:M18) | N15: =SUM(N16:N18) | O15: =SUM(O16:O18)
A16: 51350502 | B16: Monitoreo | C16: ='[9]Hoja 1'!$C$95 | D16: ='[10]Hoja 1'!$C$98 | E16: 241842440 | O16: =SUM(C16:N16)
B17: Seguridad | C17: ='[12]Hoja 1'!$G$26 | D17: ='[13]Hoja 1'!$G$26 | E17: 241842440 | O17: =SUM(C17:N17)
A18: 51355001 | B18: Transporte, fletes y acarreos | C18: ='[12]Hoja 1'!$G$29 | D18: ='[13]Hoja 1'!$G$29 | O18: =SUM(C18:N18)
B19: MANTENIMIENTO Y REPARACIONES | C19: =SUM(C20:C21) | D19: =SUM(D20:D21) | G19: =SUM(G20:G21) | H19: =SUM(H20:H21) | I19: =SUM(I20:I21) | J19: =SUM(J20:J21) | K19: =SUM(K20:K21) | L19: =SUM(L20:L21) | M19: =SUM(M20:M21) | N19: =SUM(N20:N21) | O19: =SUM(O20:O21)
A20: 51454001 | B20: Mtto Preventivo | C20: 3549011 | D20: ='[10]Hoja 1'!C131 | E20: 241842440 | O20: =SUM(C20:N20)
A21: 51454002 | B21: Mtto Correctivo | C21: 2232440 | D21: ='[10]Hoja 1'!C132 | E21: 241842440 | O21: =SUM(C21:N21)
B22: DIVERSOS | C22: =SUM(C23:C24) | D22: =SUM(D23:D24) | G22: =SUM(G23:G24) | H22: =SUM(H23:H24) | I22: =SUM(I23:I24) | J22: =SUM(J23:J24) | K22: =SUM(K23:K24) | L22: =SUM(L23:L24) | M22: =SUM(M23:M24) | N22: =SUM(N23:N24) | O22: =SUM(O23:O24)
A23: 51953501 | B23: Combustible | C23: ='[9]Hoja 1'!$C$139-964175 | D23: ='[10]Hoja 1'!$C$141-1186883 | O23: =SUM(C23:N23)
B24: Compra Equipo de Transporte | C24: 8904646 | D24: 8972985 | E24: 241842440 | O24: =SUM(C24:N24)
B25: GASTOS TOTALES | C25: =C5+C9+C11+C15+C19+C22 | D25: =D5+D9+D11+D15+D19+D22 | E25: 241842440 | G25: =G5+G9+G11+G15+G19+G22 | H25: =H5+H9+H11+H15+H19+H22 | I25: =I5+I9+I11+I15+I19+I22 | J25: =J5+J9+J11+J15+J19+J22 | K25: =K5+K9+K11+K15+K19+K22 | L25: =L5+L9+L11+L15+L19+L22 | M25: =M5+M9+M11+M15+M19+M22 | N25: =N5+N9+N11+N15+N19+N22 | O25: =O5+O9+O11+O15+O19+O22

Sheet CASINO
B2: CORPORACIÓN HACIA UN VALLE SOLIDARIO | C2: PYG CASINO 2026
B3: DIAS DE ATENCIÓN | F3: 20 | I3: 20 | L3: 20 | O3: 20 | R3: 20 | U3: 20 | X3: 20 | AA3: 20 | AD3: 20 | AG3: 20 | AJ3: 20 | AM3: =SUM(C3:AL3) | AR3: VALOR RACION | AS3: COSTO | AT3: CUPOS
C4: ENE | D4: x racion | E4: % | F4: FEB | G4: x racion | H4: % | I4: MAR | J4: x racion | K4: % | L4: ABR | M4: x racion | N4: % | O4: MAY | P4: x racion | Q4: % | R4: JUN | S4: x racion | T4: % | U4: JUL | V4: x racion | W4: % | X4: AGO | Y4: x racion | Z4: % | AA4: SEP | AB4: x racion | AC4: % | AD4: OCT | AE4: x racion | AF4: % | AG4: NOV | AH4: x racion | AI4: % | AJ4: DIC | AK4: x racion | AL4: % | AM4: ACUMULADO | AN4: x racion | AO4: %
B5: Cupos | C5: =C$3*$AR$7*$AT$4 | AM5: =C5+F5+I5+L5+O5+R5+U5+X5+AA5+AD5+AG5+AJ5 | AQ5: ALMUERZO
AM6: =C6+F6+I6+L6+O6+R6+U6+X6+AA6+AD6+AG6+AJ6 | AQ6: DESAYUNO
AM7: =C7+F7+I7+L7+O7+R7+U7+X7+AA7+AD7+AG7+AJ7 | AQ7: % Facturacion | AR7: 1
AM8: =C8+F8+I8+L8+O8+R8+U8+X8+AA8+AD8+AG8+AJ8
AM9: =C9+F9+I9+L9+O9+R9+U9+X9+AA9+AD9+AG9+AJ9
AM10: =C10+F10+I10+L10+O10+R10+U10+X10+AA10+AD10+AG10+AJ10
AM11: =C11+F11+I11+L11+O11+R11+U11+X11+AA11+AD11+AG11+AJ11
B12: TOTAL RACIONES | C12: =SUM(C5:C11) | F12: =SUM(F5:F11) | I12: =SUM(I5:I11) | L12: =SUM(L5:L11) | O12: =SUM(O5:O11) | R12: =SUM(R5:R11) | U12: =SUM(U5:U11) | X12: =SUM(X5:X11) | AA12: =SUM(AA5:AA11) | AD12: =SUM(AD5:AD11) | AG12: =SUM(AG5:AG11) | AJ12: =SUM(AJ5:AJ11) | AM12: =C12+F12+I12+L12+O12+R12+U12+X12+AA12+AD12+AG12+AJ12
B13: INGRESOS BRUTOS | C13: =C14+C23 | F13: =F14+F23 | I13: =I14+I23 | L13: =L14+L23 | O13: =O14+O23 | R13: =R14+R23 | U13: =U14+U23 | X13: =X14+X23 | AA13: =AA14+AA23 | AD13: =AD14+AD23 | AG13: =AG14+AG23 | AJ13: =AJ14+AJ23 | AM13: =C13+F13+I13+L13+O13+R13+U13+X13+AA13+AD13+AG13+AJ13
B14: OPERACIONALES | C14: =C15 | F14: =F15 | I14: =I15 | L14: =L15 | O14: =O15 | R14: =R15 | U14: =U15 | X14: =X15 | AA14: =AA15 | AD14: =AD15 | AG14: =AG15 | AJ14: =AJ15 | AM14: =C14+F14+I14+L14+O14+R14+U14+X14+AA14+AD14+AG14+AJ14
B15: INDUSTRIAS MANUFACTURERAS | C15: =SUM(C16:C22) | F15: =SUM(F16:F22) | I15: =SUM(I16:I22) | L15: =SUM(L16:L22) | O15: =SUM(O16:O22) | R15: =SUM(R16:R22) | U15: =SUM(U16:U22) | X15: =SUM(X16:X22) | AA15: =SUM(AA16:AA22) | AD15: =SUM(AD16:AD22) | AG15: =SUM(AG16:AG22) | AJ15: =SUM(AJ16:AJ22) | AM15: =C15+F15+I15+L15+O15+R15+U15+X15+AA15+AD15+AG15+AJ15
A16: 42959502 | C16: ='[9]Hoja 1'!$E$24+'[9]Hoja 1'!$E$327+'[9]Hoja 1'!$E$540+'[9]Hoja 1'!$E$604+'[9]Hoja 1'!$E$643+'[37]Hoja 1'!$E$21+'[37]Hoja 1'!$E$107+'[37]Hoja 1'!$E$144+'[37]Hoja 1'!$E$181+'[37]Hoja 1'!$E$253+'[38]Hoja 1'!$E$21+'[25]Hoja 1'!$E$23+'[39]Hoja 1'!$E$23+'[16]Hoja 1'!$F$23+'[17]Hoja 1'!$E$24 | F16: ='[10]Hoja 1'!$E$26+'[10]Hoja 1'!$E$321+'[10]Hoja 1'!$E$503+'[10]Hoja 1'!$E$575+'[18]Hoja 1'!$E$20+'[18]Hoja 1'!$E$101+'[18]Hoja 1'!$E$142+'[11]Hoja 1'!$E$21+'[40]Hoja 1'!$E$21+'[19]Hoja 1'!$E$19+'[19]Hoja 1'!$E$98+'[41]Hoja 1'!$E$23+'[42]Hoja 1'!$E$27+'[20]Hoja 1'!$E$23+'[20]Hoja 1'!$E$106+'[20]Hoja 1'!$E$147 | I16: 241842441 | L16: 241842441 | AM16: =C16+F16+I16+L16+O16+R16+U16+X16+AA16+AD16+AG16+AJ16
AM17: =C17+F17+I17+L17+O17+R17+U17+X17+AA17+AD17+AG17+AJ17
I18: =I7*$AR$6 | L18: =L7*$AR$6 | O18: =O7*$AR$6 | R18: =R7*$AR$6 | U18: =U7*$AR$6 | AM18: =C18+F18+I18+L18+O18+R18+U18+X18+AA18+AD18+AG18+AJ18
B19: NOVEDADES | AM19: =C19+F19+I19+L19+O19+R19+U19+X19+AA19+AD19+AG19+AJ19
AM20: =C20+F20+I20+L20+O20+R20+U20+X20+AA20+AD20+AG20+AJ20
AM21: =C21+F21+I21+L21+O21+R21+U21+X21+AA21+AD21+AG21+AJ21
AM22: =C22+F22+I22+L22+O22+R22+U22+X22+AA22+AD22+AG22+AJ22
B23: NO OPERACIONALES | C23: =C24 | F23: =F24 | I23: =I24 | L23: =L24 | O23: =O24 | R23: =R24 | U23: =U24 | X23: =X24 | AA23: =AA24 | AM23: =C23+F23+I23+L23+O23+R23+U23+X23+AA23+AD23+AG23+AJ23
B24: FINANCIEROS | C24: =SUM(C25:C27) | F24: =SUM(F25:F27) | I24: =SUM(I25:I27) | L24: =SUM(L25:L27) | O24: =SUM(O25:O27) | R24: =SUM(R25:R27) | U24: =SUM(U25:U27) | X24: =SUM(X25:X27) | AA24: =SUM(AA25:AA27) | AD24: =SUM(AD25:AD27) | AG24: =SUM(AG25:AG27) | AJ24: =SUM(AJ25:AJ27) | AM24: =C24+F24+I24+L24+O24+R24+U24+X24+AA24+AD24+AG24+AJ24
B25: Intereses | AM25: =C25+F25+I25+L25+O25+R25+U25+X25+AA25+AD25+AG25+AJ25
B26: Descuentos Comerciales | AM26: =C26+F26+I26+L26+O26+R26+U26+X26+AA26+AD26+AG26+AJ26
B27: otros | AM27: =C27+F27+I27+L27+O27+R27+U27+X27+AA27+AD27+AG27+AJ27
B28: DESCUENTOS - GASTO OPERACIONAL | C28: =+C29 | F28: =+F29 | I28: =+I29 | L28: =+L29 | O28: =+O29 | R28: =+R29 | U28: =+U29 | X28: =+X29 | AA28: =+AA29 | AD28: =+AD29 | AG28: =+AG29 | AJ28: =+AJ29 | AM28: =C28+F28+I28+L28+O28+R28+U28+X28+AA28+AD28+AG28+AJ28
B29: OTROS | C29: =SUM(C30:C35) | F29: =SUM(F30:F35) | H29: =F29/F13 | I29: =SUM(I30:I35) | K29: =I29/I13 | L29: =SUM(L30:L35) | N29: =L29/L13 | O29: =SUM(O30:O35) | Q29: =O29/O13 | R29: =SUM(R30:R35) | T29: =R29/R13 | U29: =SUM(U30:U35) | W29: =U29/U13 | X29: =SUM(X30:X35) | Z29: =X29/X13 | AA29: =SUM(AA30:AA35) | AC29: =AA29/AA13 | AD29: =SUM(AD30:AD35) | AF29: =AD29/AD13 | AG29: =SUM(AG30:AG35) | AI29: =AG29/AG13 | AJ29: =SUM(AJ30:AJ35) | AM29: =C29+F29+I29+L29+O29+R29+U29+X29+AA29+AD29+AG29+AJ29 | AO29: =AM29/AM13
AM30: =C30+F30+I30+L30+O30+R30+U30+X30+AA30+AD30+AG30+AJ30
AM31: =C31+F31+I31+L31+O31+R31+U31+X31+AA31+AD31+AG31+AJ31
AM32: =C32+F32+I32+L32+O32+R32+U32+X32+AA32+AD32+AG32+AJ32
AM33: =C33+F33+I33+L33+O33+R33+U33+X33+AA33+AD33+AG33+AJ33
AM34: =C34+F34+I34+L34+O34+R34+U34+X34+AA34+AD34+AG34+AJ34
AM35: =C35+F35+I35+L35+O35+R35+U35+X35+AA35+AD35+AG35+AJ35
B42: TOTAL INGRESOS NETOS | C42: =+C14+C23-C28 | F42: =+F14+F23-F28 | I42: =+I14+I23-I28 | L42: =+L14+L23-L28 | O42: =+O14+O23-O28 | R42: =+R14+R23-R28 | U42: =+U14+U23-U28 | X42: =+X14+X23-X28 | AA42: =+AA14+AA23-AA28 | AD42: =+AD14+AD23-AD28 | AG42: =+AG14+AG23-AG28 | AJ42: =+AJ14+AJ23-AJ28 | AM42: =C42+F42+I42+L42+O42+R42+U42+X42+AA42+AD42+AG42+AJ42
B44: COSTOS DE PRODUCCION | C44: =+C45+C60+C78 | F44: =+F45+F60+F78 | I44: =+I45+I60+I78 | L44: =+L45+L60+L78 | O44: =+O45+O60+O78 | R44: =+R45+R60+R78 | U44: =+U45+U60+U78 | X44: =+X45+X60+X78 | AA44: =+AA45+AA60+AA78 | AD44: =+AD45+AD60+AD78 | AG44: =+AG45+AG60+AG78 | AJ44: =+AJ45+AJ60+AJ78 | AM44: =C44+F44+I44+L44+O44+R44+U44+X44+AA44+AD44+AG44+AJ44
B45: COSTOS INDUSTRIALIZADOS | AM45: =C45+F45+I45+L45+O45+R45+U45+X45+AA45+AD45+AG45+AJ45 | AO45: =AM45/AM$13
B46: INSUMOS | AM46: =C46+F46+I46+L46+O46+R46+U46+X46+AA46+AD46+AG46+AJ46
AM47: =C47+F47+I47+L47+O47+R47+U47+X47+AA47+AD47+AG47+AJ47 | AO47: =AM47/AM$16
AM48: =C48+F48+I48+L48+O48+R48+U48+X48+AA48+AD48+AG48+AJ48
...

Sheet HUNGRIA
B2: CORPORACIÓN HACIA UN VALLE SOLIDARIO | C2: PRESUPUESTO SANTA ISABEL DE HUNGRIA 2024
B3: DIAS DE ATENCIÓN | I3: 18 | L3: 15 | O3: 21 | R3: 20 | U3: 6 | X3: 21 | AA3: 21 | AD3: 16 | AG3: 20 | AM3: =SUM(I3:AL3)
C4: ENE | D4: x racion | E4: % | F4: FEB | G4: x racion | H4: % | I4: MAR | J4: x racion | K4: % | L4: ABR | M4: x racion | N4: % | O4: MAY | P4: x racion | Q4: % | R4: JUN | S4: x racion | T4: % | U4: JUL | V4: x racion | W4: % | X4: AGO | Y4: x racion | Z4: % | AA4: SEP | AB4: x racion | AC4: % | AD4: OCT | AE4: x racion | AF4: % | AG4: NOV | AH4: x racion | AI4: % | AJ4: DIC | AK4: x racion | AL4: % | AM4: ACUMULADO | AN4: x racion | AO4: % | AQ4: REAL 2024
B5: COMPLEMENTO INDUSTRIALIZADO (Rac) | AM5: =C5+F5+I5+L5+O5+R5+U5+X5+AA5+AD5+AG5+AJ5
AM6: =C6+F6+I6+L6+O6+R6+U6+X6+AA6+AD6+AG6+AJ6
AM7: =C7+F7+I7+L7+O7+R7+U7+X7+AA7+AD7+AG7+AJ7
AM8: =C8+F8+I8+L8+O8+R8+U8+X8+AA8+AD8+AG8+AJ8
B9: NOVEDADES (Rac) | AM9: =C9+F9+I9+L9+O9+R9+U9+X9+AA9+AD9+AG9+AJ9
B12: TOTAL RACIONES | C12: =SUM(C5:C11) | F12: =SUM(F5:F11) | I12: =SUM(I5:I11) | L12: =SUM(L5:L11) | O12: =SUM(O5:O11) | R12: =SUM(R5:R11) | U12: =SUM(U5:U11) | X12: =SUM(X5:X11) | AA12: =SUM(AA5:AA11) | AD12: =SUM(AD5:AD11) | AG12: =SUM(AG5:AG11) | AJ12: =SUM(AJ5:AJ11) | AM12: =C12+F12+I12+L12+O12+R12+U12+X12+AA12+AD12+AG12+AJ12 | AQ12: =SUM(AQ5:AQ11)
B13: INGRESOS BRUTOS | C13: =C14+C23 | F13: =F14+F23 | I13: =I14+I23 | L13: =L14+L23 | O13: =O14+O23 | R13: =R14+R23 | U13: =U14+U23 | X13: =X14+X23 | AA13: =AA14+AA23 | AD13: =AD14+AD23 | AG13: =AG14+AG23 | AM13: =C13+F13+I13+L13+O13+R13+U13+X13+AA13+AD13+AG13+AJ13 | AQ13: =AQ14+AQ23
B14: OPERACIONALES | C14: =C15 | F14: =F15 | I14: =I15 | L14: =L15 | O14: =O15 | R14: =R15 | U14: =U15 | X14: =X15 | AA14: =AA15 | AD14: =AD15 | AG14: =AG15 | AM14: =C14+F14+I14+L14+O14+R14+U14+X14+AA14+AD14+AG14+AJ14 | AQ14: =AQ15
B15: INDUSTRIAS MANUFACTURERAS | C15: =C16+C17+C18+C19+C20 | F15: =F16+F17+F18+F19+F20 | H15: =F15/F15 | I15: =I16+I17+I18+I19+I20 | K15: =I15/I15 | L15: =L16+L17+L18+L19+L20 | N15: =L15/L15 | O15: =O16+O17+O18+O19+O20 | Q15: =O15/O15 | R15: =R16+R17+R18+R19+R20 | T15: =R15/R15 | U15: =U16+U17+U18+U19+U20 | X15: =X16+X17+X18+X19+X20 | Z15: =X15/X15 | AA15: =AA16+AA17+AA18+AA19+AA20 | AD15: =AD16+AD17+AD18+AD19+AD20 | AG15: =AG16+AG17+AG18+AG19+AG20 | AM15: =C15+F15+I15+L15+O15+R15+U15+X15+AA15+AD15+AG15+AJ15 | AO15: =AM15/AM15 | AQ15: =SUM(AQ16:AQ22)
B16: COMPLEMENTO INDUSTRIALIZADO (Fac) | G16: =F16/F5 | J16: =I16/I5 | M16: =L16/L5 | S16: =R16/R5 | Y16: =X16/X5 | AB16: =AA16/AA5 | AE16: =AD16/AD5 | AH16: =AG16/AG5 | AM16: =C16+F16+I16+L16+O16+R16+U16+X16+AA16+AD16+AG16+AJ16 | AO16: =AM16/AM$13 | AR16: =AQ16/AQ5
AM17: =C17+F17+I17+L17+O17+R17+U17+X17+AA17+AD17+AG17+AJ17
AM18: =C18+F18+I18+L18+O18+R18+U18+X18+AA18+AD18+AG18+AJ18
AM19: =C19+F19+I19+L19+O19+R19+U19+X19+AA19+AD19+AG19+AJ19
B20: NOVEDADES (Fac) | J20: =I20/I9 | M20: =L20/L9 | P20: =O20/O9 | S20: =R20/R9 | V20: =U20/U9 | AG20: =AG9*2497 | AM20: =C20+F20+I20+L20+O20+R20+U20+X20+AA20+AD20+AG20+AJ20
B23: NO OPERACIONALES | C23: =C24 | F23: =F24 | I23: =I24 | L23: =L24 | O23: =O24 | R23: =R24 | U23: =U24 | X23: =X24 | AA23: =AA24 | AD23: =AD24 | AG23: =AG24 | AM23: =C23+F23+I23+L23+O23+R23+U23+X23+AA23+AD23+AG23+AJ23
B24: FINANCIEROS | C24: =SUM(C25:C27) | F24: =SUM(F25:F27) | I24: =SUM(I25:I27) | L24: =SUM(L25:L27) | O24: =SUM(O25:O27) | R24: =SUM(R25:R27) | U24: =SUM(U25:U27) | X24: =X25+X26+X27 | AA24: =AA25+AA26+AA27 | AD24: =AD25+AD26+AD27 | AG24: =AG25+AG26+AG27 | AM24: =C24+F24+I24+L24+O24+R24+U24+X24+AA24+AD24+AG24+AJ24
B25: Intereses | AM25: =C25+F25+I25+L25+O25+R25+U25+X25+AA25+AD25+AG25+AJ25
B26: Descuentos Comerciales | AM26: =C26+F26+I26+L26+O26+R26+U26+X26+AA26+AD26+AG26+AJ26
B27: otros Fin | AM27: =C27+F27+I27+L27+O27+R27+U27+X27+AA27+AD27+AG27+AJ27
B28: DESCUENTOS - GASTO OPERACIONAL | C28: =+C29 | F28: =+F29 | I28: =+I29 | L28: =+L29 | O28: =+O29 | R28: =+R29 | U28: =+U29 | X28: =+X29 | AA28: =+AA29 | AD28: =+AD29 | AG28: =+AG29 | AM28: =C28+F28+I28+L28+O28+R28+U28+X28+AA28+AD28+AG28+AJ28 | AQ28: =+AQ29
B29: OTROS | C29: =SUM(C30:C35) | F29: =SUM(F30:F35) | H29: =F29/F13 | I29: =SUM(I30:I35) | K29: =I29/I13 | L29: =SUM(L30:L35) | N29: =L29/L13 | O29: =SUM(O30:O35) | R29: =SUM(R30:R35) | U29: =SUM(U30:U35) | X29: =SUM(X30:X35) | AA29: =SUM(AA30:AA35) | AD29: =SUM(AD30:AD35) | AG29: =SUM(AG30:AG35) | AM29: =C29+F29+I29+L29+O29+R29+U29+X29+AA29+AD29+AG29+AJ29 | AO29: =AM29/AM13 | AQ29: =SUM(AQ30:AQ35)
B30: ICA (0.77%) | C30: =C15*0.77% | F30: =F13*0.77% | I30: =I13*0.77% | L30: =L13*0.77% | O30: =O13*0.77% | R30: =R13*0.77% | U30: =U13*0.77% | AA30: =AA13*0.77% | AD30: =AD13*0.77% | AG30: =AG13*0.77% | AM30: =C30+F30+I30+L30+O30+R30+U30+X30+AA30+AD30+AG30+AJ30
AM31: =C31+F31+I31+L31+O31+R31+U31+X31+AA31+AD31+AG31+AJ31
AM32: =C32+F32+I32+L32+O32+R32+U32+X32+AA32+AD32+AG32+AJ32
AM33: =C33+F33+I33+L33+O33+R33+U33+X33+AA33+AD33+AG33+AJ33
AM34: =C34+F34+I34+L34+O34+R34+U34+X34+AA34+AD34+AG34+AJ34
AM35: =C35+F35+I35+L35+O35+R35+U35+X35+AA35+AD35+AG35+AJ35
B42: TOTAL INGRESOS NETOS | C42: =+C14+C23-C28 | F42: =+F14+F23-F28 | I42: =+I14+I23-I28 | L42: =+L14+L23-L28 | O42: =+O14+O23-O28 | R42: =+R14+R23-R28 | U42: =+U14+U23-U28 | X42: =+X14+X23-X28 | AA42: =+AA14+AA23-AA28 | AD42: =+AD14+AD23-AD28 | AG42: =+AG14+AG23-AG28 | AM42: =C42+F42+I42+L42+O42+R42+U42+X42+AA42+AD42+AG42+AJ42 | AQ42: =+AQ14+AQ23-AQ28
AS43: =(AQ46+AQ61)/(AQ13)
B44: COSTOS DE PRODUCCION | C44: =+C45+C60+C78 | F44: =+F45+F60+F78 | H44: =F44/F$13 | I44: =+I45+I60+I78 | K44: =I44/I$13 | L44: =+L45+L60+L78 | N44: =L44/L$13 | O44: =+O45+O60+O78 | Q44: =O44/O$13 | R44: =+R45+R60+R78 | T44: =R44/R$13 | U44: =+U45+U60+U78 | W44: =U44/U$13 | X44: =+X45+X60+X78 | Z44: =X44/X$13 | AA44: =+AA45+AA60+AA78 | AD44: =+AD45+AD60+AD78 | AG44: =+AG45+AG60+AG78 | AJ44: =+AJ45+AJ60+AJ78 | AM44: =C44+F44+I44+L44+O44+R44+U44+X44+AA44+AD44+AG44+AJ44 | AO44: =AM44/AM$13 | AQ44: =+AQ45+AQ60+AQ78 | AS44: =AQ44/AQ$13
B45: COSTOS INDUSTRIALIZADOS | C45: =+C46+C58+C59 | F45: =+F46+F57 | I45: =+I46+I57 | L45: =+L46+L57 | O45: =+O46+O57 | R45: =+R46+R57 | U45: =+U46+U57 | X45: =+X46+X57 | AA45: =+AA46+AA57 | AD45: =+AD46+AD57 | AG45: =+AG46+AG57 | AJ45: =+AJ46+AJ57 | AM45: =C45+F45+I45+L45+O45+R45+U45+X45+AA45+AD45+AG45+AJ45 | AO45: =AM45/AM$13 | AQ45: =+AQ46+AQ57
B46: INSUMOS CI | C46: =SUM(C47:C56)+C57 | F46: =SUM(F47:F56) | I46: =SUM(I47:I56) | L46: =SUM(L47:L56) | O46: =SUM(O47:O56) | R46: =SUM(R47:R56) | U46: =SUM(U47:U56) | X46: =SUM(X47:X56) | AA46: =SUM(AA47:AA56) | AD46: =SUM(AD47:AD56) | AG46: =SUM(AG47:AG56) | AJ46: =SUM(AJ47:AJ56) | AM46: =C46+F46+I46+L46+O46+R46+U46+X46+AA46+AD46+AG46+AJ46 | AO46: =AM46/AM13 | AQ46: =SUM(AQ47:AQ56)
B47: COMPLEMENTO INDUSTRIALIZADO (Ins) | G47: =F47/F5 | H47: =F47/F16 | J47: =I47/I5 | K47: =I47/I16 | M47: =L47/L5 | N47: =L47/L16 | P47: =O47/O12 | Q47: =O47/O15 | S47: =R47/R5 | T47: =R47/R16 | V47: =U47/U12 | W47: =U47/U15 | Y47: =X47/X5 | Z47: =X47/X16 | AB47: =AA47/AA12 | AC47: =AA47/AA15 | AE47: =AD47/AD12 | AF47: =AD47/AD15 | AH47: =AG47/AG5 | AI47: =AG47/AG15 | AM47: =C47+F47+I47+L47+O47+R47+U47+X47+AA47+AD47+AG47+AJ47 | AN47: =AM47/AM5 | AO47: =AM47/AM16 | AR47: =AQ47/AQ5 | AS47: =AQ47/AQ16
AM48: =C48+F48+I48+L48+O48+R48+U48+X48+AA48+AD48+AG48+AJ48
AM49: =C49+F49+I49+L49+O49+R49+U49+X49+AA49+AD49+AG49+AJ49
AM50: =C50+F50+I50+L50+O50+R50+U50+X50+AA50+AD50+AG50+AJ50
AM51: =C51+F51+I51+L51+O51+R51+U51+X51+AA51+AD51+AG51+AJ51
...

Sheet CALI
B2: CORPORACIÓN HACIA UN VALLE SOLIDARIO | C2: PYG CALI 2026
B3: DIAS DE ATENCIÓN | C3: 5 | F3: 20 | I3: 19 | L3: 19 | O3: 19 | R3: 18 | U3: 9 | X3: 19 | AA3: 22 | AD3: 16 | AG3: 19 | AJ3: 4 | AM3: =SUM(C3:AJ3)
C4: ENE | D4: x racion | E4: % | F4: FEB | G4: x racion | H4: % | I4: MAR | J4: x racion | K4: % | L4: ABR | M4: x racion | N4: % | O4: MAY | P4: x racion | Q4: % | R4: JUN | S4: x racion | T4: % | U4: JUL | V4: x racion | W4: % | X4: AGO | Y4: x racion | Z4: % | AA4: SEP | AB4: x racion | AC4: % | AD4: OCT | AE4: x racion | AF4: % | AG4: NOV | AH4: x racion | AI4: % | AJ4: DIC | AK4: x racion | AL4: % | AM4: ACUMULADO | AN4: x racion | AO4: %
B5: COMPLEMENTO INDUSTRIALIZADO | AM5: =C5+F5+I5+L5+O5+R5+U5+X5+AA5+AD5+AG5+AJ5 | AO5: =AM5/AM12
B6: COMPLEMENTO PREPARADO AM | AM6: =C6+F6+I6+L6+O6+R6+U6+X6+AA6+AD6+AG6+AJ6 | AO6: =AM6/AM12
B7: COMPLEMENTO PREPARADO PM | AM7: =C7+F7+I7+L7+O7+R7+U7+X7+AA7+AD7+AG7+AJ7 | AO7: =AM7/AM12
B8: ALMUERZO JORNADA UNICA | AM8: =C8+F8+I8+L8+O8+R8+U8+X8+AA8+AD8+AG8+AJ8
B9: NOVEDADES | AM9: =C9+F9+I9+L9+O9+R9+U9+X9+AA9+AD9+AG9+AJ9
AM10: =C10+F10+I10+L10+O10+R10+U10+X10+AA10+AD10+AG10+AJ10
AM11: =C11+F11+I11+L11+O11+R11+U11+X11+AA11+AD11+AG11+AJ11
B12: TOTAL RACIONES | C12: =SUM(C5:C11) | F12: =SUM(F5:F11) | I12: =SUM(I5:I11) | L12: =SUM(L5:L11) | O12: =SUM(O5:O11) | R12: =SUM(R5:R11) | U12: =SUM(U5:U11) | X12: =SUM(X5:X11) | AA12: =SUM(AA5:AA11) | AD12: =SUM(AD5:AD11) | AG12: =SUM(AG5:AG11) | AJ12: =SUM(AJ5:AJ11) | AM12: =C12+F12+I12+L12+O12+R12+U12+X12+AA12+AD12+AG12+AJ12
B13: INGRESOS BRUTOS | C13: =C14+C23 | F13: =F14+F23 | I13: =I14+I23 | L13: =L14+L23 | O13: =O14+O23 | R13: =R14+R23 | U13: =U14+U23 | X13: =X14+X23 | AA13: =AA14+AA23 | AD13: =AD14+AD23 | AG13: =AG14+AG23 | AJ13: =AJ14+AJ23 | AM13: =C13+F13+I13+L13+O13+R13+U13+X13+AA13+AD13+AG13+AJ13
B14: OPERACIONALES | C14: =C15 | F14: =F15 | I14: =I15 | L14: =L15 | O14: =O15 | R14: =R15 | U14: =U15 | X14: =X15 | AA14: =AA15 | AD14: =AD15 | AG14: =AG15 | AJ14: =AJ15 | AM14: =C14+F14+I14+L14+O14+R14+U14+X14+AA14+AD14+AG14+AJ14
B15: INDUSTRIAS MANUFACTURERAS | C15: =SUM(C16:C22) | F15: =SUM(F16:F22) | I15: =SUM(I16:I22) | L15: =SUM(L16:L22) | O15: =SUM(O16:O22) | R15: =SUM(R16:R22) | U15: =SUM(U16:U22) | X15: =SUM(X16:X22) | AA15: =SUM(AA16:AA22) | AC15: =AA15/AA15 | AD15: =SUM(AD16:AD22) | AG15: =SUM(AG16:AG22) | AI15: =AG15/AG15 | AJ15: =SUM(AJ16:AJ22) | AM15: =C15+F15+I15+L15+O15+R15+U15+X15+AA15+AD15+AG15+AJ15 | AO15: =AM15/AM15
B16: COMPLEMENTO INDUSTRIALIZADO | D16: =C16/C5 | AM16: =C16+F16+I16+L16+O16+R16+U16+X16+AA16+AD16+AG16+AJ16 | AO16: =AM16/AM$13
B17: COMPLEMENTO PREPARADO AM | D17: =C17/C6 | AM17: =C17+F17+I17+L17+O17+R17+U17+X17+AA17+AD17+AG17+AJ17 | AO17: =AM17/AM$13
B18: COMPLEMENTO PREPARADO PM | D18: =C18/C7 | AM18: =C18+F18+I18+L18+O18+R18+U18+X18+AA18+AD18+AG18+AJ18 | AO18: =AM18/AM$13
B19: ALMUERZO JORNADA UNICA | D19: =C19/C8 | AM19: =C19+F19+I19+L19+O19+R19+U19+X19+AA19+AD19+AG19+AJ19 | AO19: =AM19/AM$13
B20: NOVEDADES | AM20: =C20+F20+I20+L20+O20+R20+U20+X20+AA20+AD20+AG20+AJ20
AM21: =C21+F21+I21+L21+O21+R21+U21+X21+AA21+AD21+AG21+AJ21
AM22: =C22+F22+I22+L22+O22+R22+U22+X22+AA22+AD22+AG22+AJ22
B23: NO OPERACIONALES | C23: =C24 | F23: =F24 | I23: =I24 | L23: =L24 | O23: =O24 | R23: =R24 | U23: =U24 | X23: =X24 | AA23: =AA24 | AD23: =AD24 | AG23: =AG24 | AJ23: =AJ24 | AM23: =C23+F23+I23+L23+O23+R23+U23+X23+AA23+AD23+AG23+AJ23
B24: FINANCIEROS | C24: =SUM(C25:C27) | F24: =SUM(F25:F27) | I24: =SUM(I25:I27) | L24: =SUM(L25:L27) | O24: =SUM(O25:O27) | R24: =SUM(R25:R27) | U24: =SUM(U25:U27) | X24: =SUM(X25:X27) | AA24: =SUM(AA25:AA27) | AD24: =SUM(AD25:AD27) | AG24: =SUM(AG25:AG27) | AJ24: =SUM(AJ25:AJ27) | AM24: =C24+F24+I24+L24+O24+R24+U24+X24+AA24+AD24+AG24+AJ24
B25: Intereses | AM25: =C25+F25+I25+L25+O25+R25+U25+X25+AA25+AD25+AG25+AJ25
B26: Descuentos Comerciales | AM26: =C26+F26+I26+L26+O26+R26+U26+X26+AA26+AD26+AG26+AJ26
B27: otros Fin | AM27: =C27+F27+I27+L27+O27+R27+U27+X27+AA27+AD27+AG27+AJ27
B28: DESCUENTOS - GASTO OPERACIONAL | C28: =+C29 | F28: =+F29 | I28: =+I29 | L28: =+L29 | O28: =+O29 | R28: =+R29 | U28: =+U29 | X28: =+X29 | AA28: =+AA29 | AD28: =+AD29 | AG28: =+AG29 | AJ28: =+AJ29 | AM28: =C28+F28+I28+L28+O28+R28+U28+X28+AA28+AD28+AG28+AJ28
B29: OTROS | C29: =SUM(C30:C35) | E29: =C29/C13 | F29: =SUM(F30:F35) | H29: =F29/F13 | I29: =SUM(I30:I35) | K29: =I29/I13 | L29: =SUM(L30:L35) | N29: =L29/L13 | O29: =SUM(O30:O35) | Q29: =O29/O13 | R29: =SUM(R30:R35) | T29: =R29/R13 | U29: =SUM(U30:U35) | W29: =U29/U13 | X29: =SUM(X30:X35) | Z29: =X29/X13 | AA29: =SUM(AA30:AA35) | AC29: =AA29/AA13 | AD29: =SUM(AD30:AD35) | AF29: =AD29/AD13 | AG29: =SUM(AG30:AG35) | AI29: =AG29/AG13 | AJ29: =SUM(AJ30:AJ41) | AM29: =C29+F29+I29+L29+O29+R29+U29+X29+AA29+AD29+AG29+AJ29 | AO29: =AM29/AM13
B30: 2% Estampillas Prounivalle | C30: =C$13*2% | F30: =F$13*2% | I30: =I$13*2% | L30: =L$13*2% | O30: =O$13*2% | R30: =R$13*2% | U30: =U$13*2% | X30: =X$13*2% | AA30: =AA$13*2% | AD30: =AD$13*2% | AG30: =AG$13*2% | AJ30: =AJ$13*2% | AM30: =C30+F30+I30+L30+O30+R30+U30+X30+AA30+AD30+AG30+AJ30
B31: 0,88% Rte Ica | C31: =C$13*0.88% | F31: =F$13*0.88% | I31: =I$13*0.88% | L31: =L$13*0.88% | O31: =O$13*0.88% | R31: =R$13*0.88% | U31: =U$13*0.88% | X31: =X$13*0.88% | AA31: =AA$13*0.88% | AD31: =AD$13*0.88% | AG31: =AG$13*0.88% | AJ31: =AJ$13*0.88% | AM31: =C31+F31+I31+L31+O31+R31+U31+X31+AA31+AD31+AG31+AJ31
B32: 1% Estampilla Prohospital | C32: =C$13*1% | F32: =F$13*1% | I32: =I$13*1% | L32: =L$13*1% | O32: =O$13*1% | R32: =R$13*1% | U32: =U$13*1% | X32: =X$13*1% | AA32: =AA$13*1% | AD32: =AD$13*1% | AG32: =AG$13*1% | AJ32: =AJ$13*1% | AM32: =C32+F32+I32+L32+O32+R32+U32+X32+AA32+AD32+AG32+AJ32
B33: 0,5% Propacifico | C33: =C$13*0.5% | F33: =F$13*0.5% | I33: =I$13*0.5% | L33: =L$13*0.5% | O33: =O$13*0.5% | R33: =R$13*0.5% | U33: =U$13*0.5% | X33: =X$13*0.5% | AA33: =AA$13*0.5% | AD33: =AD$13*0.5% | AG33: =AG$13*0.5% | AJ33: =AJ$13*0.5% | AM33: =C33+F33+I33+L33+O33+R33+U33+X33+AA33+AD33+AG33+AJ33
B34: Retefuente | C34: =(C$13*3.5%)*1% | F34: =(F$13*3.5%)*1% | I34: =(I$13*3.5%)*1% | L34: =(L$13*3.5%)*1% | O34: =(O$13*3.5%)*1% | R34: =(R$13*3.5%)*1% | U34: =(U$13*3.5%)*1% | X34: =(X$13*3.5%)*1% | AA34: =(AA$13*3.5%)*1% | AD34: =(AD$13*3.5%)*1% | AG34: =(AG$13*3.5%)*1% | AJ34: =(AJ$13*3.5%)*1% | AM34: =C34+F34+I34+L34+O34+R34+U34+X34+AA34+AD34+AG34+AJ34
B35: 2% Juzgado de Familia | C35: =C13*2% | F35: =F13*2% | I35: =I13*2% | L35: =L13*2% | O35: =O13*2% | R35: =R13*2% | U35: =U13*2% | X35: =X13*2% | AA35: =AA13*2% | AD35: =AD13*2% | AG35: =AG13*2% | AJ35: =AJ13*2% | AM35: =C35+F35+I35+L35+O35+R35+U35+X35+AA35+AD35+AG35+AJ35
AM36: =C36+F36+I36+L36+O36+R36+U36+X36+AA36+AD36+AG36+AJ36
B42: TOTAL INGRESOS NETOS | C42: =+C14+C23-C28 | F42: =+F14+F23-F28 | I42: =+I14+I23-I28 | L42: =+L14+L23-L28 | O42: =+O14+O23-O28 | R42: =+R14+R23-R28 | U42: =+U14+U23-U28 | X42: =+X14+X23-X28 | AA42: =+AA14+AA23-AA28 | AD42: =+AD14+AD23-AD28 | AG42: =+AG14+AG23-AG28 | AJ42: =+AJ14+AJ23-AJ28 | AM42: =C42+F42+I42+L42+O42+R42+U42+X42+AA42+AD42+AG42+AJ42
E43: =(C46+C61)/(C13-C20) | H43: =(F46+F61)/(F13-F20) | K43: =(I46+I61)/(I13-I20) | N43: =(L46+L61)/(L13-L20) | Q43: =(O46+O61)/(O13-O20) | T43: =(R46+R61)/(R13-R20) | W43: =(U46+U61)/U13 | Z43: =(X46+X61)/X13 | AC43: =(AA46+AA61)/AA13 | AF43: =(AD46+AD61)/AD13 | AI43: =(AG46+AG61)/(AG13-AG20) | AL43: =(AJ46+AJ61)/(AJ13-AJ20) | AO43: =(AM46+AM61)/(AM13-AM20)
B44: COSTOS DE PRODUCCION | C44: =+C45+C60+C78 | E44: =C44/C$13 | F44: =+F45+F60+F78 | H44: =F44/F$13 | I44: =+I45+I60+I78 | K44: =I44/I$13 | L44: =+L45+L60+L78 | N44: =L44/L$13 | O44: =+O45+O60+O78 | Q44: =O44/O$13 | R44: =+R45+R60+R78 | T44: =R44/R$13 | U44: =+U45+U60+U78 | W44: =U44/U$13 | X44: =+X45+X60+X78 | Z44: =X44/X$13 | AA44: =+AA45+AA60+AA78 | AC44: =AA44/AA$13 | AD44: =+AD45+AD60+AD78 | AF44: =AD44/AD$13 | AG44: =+AG45+AG60+AG78 | AI44: =AG44/AG$13 | AJ44: =+AJ45+AJ60+AJ78 | AM44: =C44+F44+I44+L44+O44+R44+U44+X44+AA44+AD44+AG44+AJ44 | AO44: =AM44/AM$13
B45: COSTOS INDUSTRIALIZADOS | C45: =+C46+C57 | E45: =C45/C13 | F45: =+F46+F57 | H45: =F45/F13 | I45: =+I46+I57 | K45: =I45/I13 | L45: =+L46+L57 | N45: =L45/L13 | O45: =+O46+O57 | Q45: =O45/O13 | R45: =+R46+R57 | T45: =R45/R13 | U45: =+U46+U57 | W45: =U45/U13 | X45: =+X46+X57 | Z45: =X45/X13 | AA45: =+AA46+AA57 | AC45: =AA45/AA13 | AD45: =+AD46+AD57 | AF45: =AD45/AD13 | AG45: =+AG46+AG57 | AI45: =AG45/AG13 | AJ45: =+AJ46+AJ57 | AM45: =C45+F45+I45+L45+O45+R45+U45+X45+AA45+AD45+AG45+AJ45
B46: INSUMOS CI | C46: =SUM(C47:C56) | F46: =SUM(F47:F56) | I46: =SUM(I47:I56) | L46: =SUM(L47:L56) | O46: =SUM(O47:O56) | R46: =SUM(R47:R56) | U46: =SUM(U47:U56) | X46: =SUM(X47:X56) | Z46: =X46/X13 | AA46: =SUM(AA47:AA56) | AC46: =AA46/AA13 | AD46: =SUM(AD47:AD56) | AF46: =AD46/AD13 | AG46: =SUM(AG47:AG56) | AI46: =AG46/AG13 | AJ46: =SUM(AJ47:AJ56) | AM46: =C46+F46+I46+L46+O46+R46+U46+X46+AA46+AD46+AG46+AJ46
...

Sheet YUMBO
B2: CORPORACIÓN HACIA UN VALLE SOLIDARIO | C2: PYG YUMBO 2026
B3: DIAS DE ATENCIÓN | C3: 5 | F3: 20 | I3: 19 | L3: 19 | O3: 19 | R3: 13 | U3: 14 | X3: 19 | AA3: 22 | AD3: 16 | AG3: 19 | AJ3: 4 | AM3: =SUM(C3:AL3)
C4: ENE | D4: x racion | E4: % | F4: FEB | G4: x racion | H4: % | I4: MAR | J4: x racion | K4: % | L4: ABR | M4: x racion | N4: % | O4: MAY | P4: x racion | Q4: % | R4: JUN | S4: x racion | T4: % | U4: JUL | V4: x racion | W4: % | X4: AGO | Y4: x racion | Z4: % | AA4: SEP | AB4: x racion | AC4: % | AD4: OCT | AE4: x racion | AF4: % | AG4: NOV | AH4: x racion | AI4: % | AJ4: DIC | AK4: x racion | AL4: % | AM4: ACUMULADO | AN4: x racion | AO4: %
B5: COMPLEMENTO AM/PM (Rac) | AM5: =C5+F5+I5+L5+O5+R5+U5+X5+AA5+AD5+AG5+AJ5 | AO5: =AM5/AM12
B6: REFUERZO COMPLEMENTO AM/PM (Rac) | AM6: =C6+F6+I6+L6+O6+R6+U6+X6+AA6+AD6+AG6+AJ6 | AO6: =AM6/AM12
B7: ALMUERZO JORNADA UNICA (Rac) | AM7: =C7+F7+I7+L7+O7+R7+U7+X7+AA7+AD7+AG7+AJ7 | AO7: =AM7/AM12
AM8: =C8+F8+I8+L8+O8+R8+U8+X8+AA8+AD8+AG8+AJ8
B9: NOVEDADES (Rac) | AM9: =C9+F9+I9+L9+O9+R9+U9+X9+AA9+AD9+AG9+AJ9
AM10: =C10+F10+I10+L10+O10+R10+U10+X10+AA10+AD10+AG10+AJ10
AM11: =C11+F11+I11+L11+O11+R11+U11+X11+AA11+AD11+AG11+AJ11
B12: TOTAL RACIONES | C12: =SUM(C5:C11) | F12: =SUM(F5:F11) | I12: =SUM(I5:I11) | L12: =SUM(L5:L11) | O12: =SUM(O5:O11) | R12: =SUM(R5:R11) | U12: =SUM(U5:U11) | X12: =SUM(X5:X11) | AA12: =SUM(AA5:AA11) | AD12: =SUM(AD5:AD11) | AG12: =SUM(AG5:AG11) | AJ12: =SUM(AJ5:AJ11) | AM12: =C12+F12+I12+L12+O12+R12+U12+X12+AA12+AD12+AG12+AJ12
B13: INGRESOS BRUTOS | C13: =C14+C23 | F13: =F14+F23 | I13: =I14+I23 | L13: =L14+L23 | O13: =O14+O23 | R13: =R14+R23 | U13: =U14+U23 | X13: =X14+X23 | AA13: =AA14+AA23 | AD13: =AD14+AD23 | AG13: =AG14+AG23 | AJ13: =AJ14+AJ23 | AM13: =C13+F13+I13+L13+O13+R13+U13+X13+AA13+AD13+AG13+AJ13
B14: OPERACIONALES | C14: =C15 | F14: =F15 | I14: =I15 | L14: =L15 | O14: =O15 | R14: =R15 | U14: =U15 | X14: =X15 | AA14: =AA15 | AD14: =AD15 | AG14: =AG15 | AJ14: =AJ15 | AM14: =C14+F14+I14+L14+O14+R14+U14+X14+AA14+AD14+AG14+AJ14
B15: INDUSTRIAS MANUFACTURERAS | C15: =SUM(C16:C22) | F15: =SUM(F16:F22) | I15: =SUM(I16:I22) | L15: =SUM(L16:L22) | O15: =SUM(O16:O22) | R15: =SUM(R16:R22) | U15: =SUM(U16:U22) | X15: =SUM(X16:X22) | AA15: =SUM(AA16:AA22) | AD15: =SUM(AD16:AD22) | AG15: =SUM(AG16:AG22) | AJ15: =SUM(AJ16:AJ22) | AM15: =C15+F15+I15+L15+O15+R15+U15+X15+AA15+AD15+AG15+AJ15 | AO15: =AM15/AM15
B16: COMPLEMENTO AM/PM (Fac) | D16: =C16/C5 | G16: =F16/F5 | AM16: =C16+F16+I16+L16+O16+R16+U16+X16+AA16+AD16+AG16+AJ16
B17: REFUERZO COMPLEMENTO AM/PM (Fac) | D17: =C17/C6 | G17: =F17/F6 | AM17: =C17+F17+I17+L17+O17+R17+U17+X17+AA17+AD17+AG17+AJ17
B18: ALMUERZO JORNADA UNICA (Fac) | D18: =C18/C7 | G18: =F18/F7 | AM18: =C18+F18+I18+L18+O18+R18+U18+X18+AA18+AD18+AG18+AJ18
AM19: =C19+F19+I19+L19+O19+R19+U19+X19+AA19+AD19+AG19+AJ19
B20: NOVEDADES (Fac) | AM20: =C20+F20+I20+L20+O20+R20+U20+X20+AA20+AD20+AG20+AJ20
AM21: =C21+F21+I21+L21+O21+R21+U21+X21+AA21+AD21+AG21+AJ21
AM22: =C22+F22+I22+L22+O22+R22+U22+X22+AA22+AD22+AG22+AJ22
B23: NO OPERACIONALES | C23: =C24 | F23: =F24 | I23: =I24 | L23: =L24 | O23: =O24 | R23: =R24 | U23: =U24 | X23: =X24 | AA23: =AA24 | AM23: =C23+F23+I23+L23+O23+R23+U23+X23+AA23+AD23+AG23+AJ23
B24: FINANCIEROS | C24: =SUM(C25:C27) | F24: =SUM(F25:F27) | I24: =SUM(I25:I27) | L24: =SUM(L25:L27) | O24: =SUM(O25:O27) | R24: =SUM(R25:R27) | U24: =SUM(U25:U27) | X24: =SUM(X25:X27) | AA24: =SUM(AA25:AA27) | AD24: =SUM(AD25:AD27) | AG24: =SUM(AG25:AG27) | AJ24: =SUM(AJ25:AJ27) | AM24: =C24+F24+I24+L24+O24+R24+U24+X24+AA24+AD24+AG24+AJ24
B25: Intereses | AM25: =C25+F25+I25+L25+O25+R25+U25+X25+AA25+AD25+AG25+AJ25
B26: Descuentos Comerciales | AM26: =C26+F26+I26+L26+O26+R26+U26+X26+AA26+AD26+AG26+AJ26
B27: otros Fin | AM27: =C27+F27+I27+L27+O27+R27+U27+X27+AA27+AD27+AG27+AJ27
B28: DESCUENTOS - GASTO OPERACIONAL | C28: =+C29 | F28: =+F29 | I28: =+I29 | L28: =+L29 | O28: =+O29 | R28: =+R29 | U28: =+U29 | X28: =+X29 | AA28: =+AA29 | AD28: =+AD29 | AG28: =+AG29 | AJ28: =+AJ29 | AM28: =C28+F28+I28+L28+O28+R28+U28+X28+AA28+AD28+AG28+AJ28
B29: OTROS | C29: =SUM(C30:C37) | E29: =C29/C13 | F29: =SUM(F30:F37) | H29: =F29/F13 | I29: =SUM(I30:I37) | K29: =I29/I13 | L29: =SUM(L30:L37) | N29: =L29/L13 | O29: =SUM(O30:O37) | Q29: =O29/O13 | R29: =SUM(R30:R37) | T29: =R29/R13 | U29: =SUM(U30:U37) | W29: =U29/U13 | X29: =SUM(X30:X38) | Z29: =X29/X13 | AA29: =SUM(AA30:AA38) | AC29: =AA29/AA13 | AD29: =SUM(AD30:AD38) | AF29: =AD29/AD13 | AG29: =SUM(AG30:AG38) | AI29: =AG29/AG13 | AJ29: =SUM(AJ30:AJ41) | AM29: =C29+F29+I29+L29+O29+R29+U29+X29+AA29+AD29+AG29+AJ29 | AO29: =AM29/AM13
B30: Procultura 0,5% | C30: =C$13*0.5% | F30: =F$13*0.5% | I30: =I$13*0.5% | L30: =L$13*0.5% | O30: =O$13*0.5% | R30: =R$13*0.5% | U30: =U$13*0.5% | X30: =X$13*0.5% | AA30: =AA$13*0.5% | AD30: =AD$13*0.5% | AG30: =AG$13*0.5% | AJ30: =AJ$13*0.5% | AM30: =C30+F30+I30+L30+O30+R30+U30+X30+AA30+AD30+AG30+AJ30
B31: Prohospitales 1% | C31: =C$13*1% | F31: =F$13*1% | I31: =I$13*1% | L31: =L$13*1% | O31: =O$13*1% | R31: =R$13*1% | U31: =U$13*1% | X31: =X$13*1% | AA31: =AA$13*1% | AD31: =AD$13*1% | AG31: =AG$13*1% | AJ31: =AJ$13*1% | AM31: =C31+F31+I31+L31+O31+R31+U31+X31+AA31+AD31+AG31+AJ31
B32: Rete Ica 0,6% | C32: =(C13*80%)*0.6% | F32: =(F13*80%)*0.6% | I32: =(I13*1%)*0.6% | L32: =(L13*1%)*0.6% | O32: =(O13*1%)*0.6% | R32: =(R13*1%)*0.6% | U32: =(U13*1%)*0.6% | X32: =(X13*1%)*0.6% | AA32: =(AA13*1%)*0.6% | AD32: =(AD13*1%)*0.6% | AG32: =(AG13*1%)*0.6% | AJ32: =(AJ13*1%)*0.6% | AM32: =C32+F32+I32+L32+O32+R32+U32+X32+AA32+AD32+AG32+AJ32
B33: Adulto Mayor 2% | C33: =C13*2% | F33: =F13*2% | I33: =I13*2% | L33: =L13*2% | O33: =O13*2% | R33: =R13*2% | U33: =U13*2% | X33: =X13*2% | AA33: =AA13*2% | AD33: =AD13*2% | AG33: =AG13*2% | AJ33: =AJ13*2% | AM33: =C33+F33+I33+L33+O33+R33+U33+X33+AA33+AD33+AG33+AJ33
B34: Retefuente | I34: =(I13*1%)*3.5% | L34: =(L13*1%)*3.5% | O34: =(O13*1%)*3.5% | R34: =(R13*1%)*3.5% | U34: =(U13*1%)*3.5% | X34: =(X13*1%)*3.5% | AA34: =(AA13*1%)*3.5% | AD34: =(AD13*1%)*3.5% | AG34: =(AG13*1%)*3.5% | AJ34: =(AJ13*1%)*3.5% | AM34: =C34+F34+I34+L34+O34+R34+U34+X34+AA34+AD34+AG34+AJ34
B35: Prodeporte 2,5% | C35: =C$13*2.5% | F35: =F$13*2.5% | I35: =I$13*2.5% | L35: =L$13*2.5% | O35: =O$13*2.5% | R35: =R$13*2.5% | U35: =U$13*2.5% | X35: =X$13*2.5% | AA35: =AA$13*2.5% | AD35: =AD$13*2.5% | AG35: =AG$13*2.5% | AJ35: =AJ$13*2.5% | AM35: =C35+F35+I35+L35+O35+R35+U35+X35+AA35+AD35+AG35+AJ35
B36: 2% Juzgado de Familia | C36: =C13*2% | F36: =F13*2% | I36: =I13*2% | L36: =L13*2% | O36: =O13*2% | R36: =R13*2% | U36: =U13*2% | X36: =X13*2% | AA36: =AA13*2% | AD36: =AD13*2% | AG36: =AG13*2% | AJ36: =AJ13*2% | AM36: =C36+F36+I36+L36+O36+R36+U36+X36+AA36+AD36+AG36+AJ36
B37: 0,5% Propacifico | C37: =C$13*0.5% | F37: =F$13*0.5% | I37: =I$13*0.5% | L37: =L$13*0.5% | O37: =O$13*0.5% | R37: =R$13*0.5% | U37: =U$13*0.5% | X37: =X$13*0.5% | AA37: =AA$13*0.5% | AD37: =AD$13*0.5% | AG37: =AG$13*0.5% | AJ37: =AJ$13*0.5% | AM37: =C37+F37+I37+L37+O37+R37+U37+X37+AA37+AD37+AG37+AJ37
AM38: =C38+F38+I38+L38+O38+R38+U38+X38+AA38+AD38+AG38+AJ38
B42: TOTAL INGRESOS NETOS | C42: =+C14+C23-C28 | F42: =+F14+F23-F28 | I42: =+I14+I23-I28 | L42: =+L14+L23-L28 | O42: =+O14+O23-O28 | R42: =+R14+R23-R28 | U42: =+U14+U23-U28 | X42: =+X14+X23-X28 | AA42: =+AA14+AA23-AA28 | AD42: =+AD14+AD23-AD28 | AG42: =+AG14+AG23-AG28 | AJ42: =+AJ14+AJ23-AJ28 | AM42: =C42+F42+I42+L42+O42+R42+U42+X42+AA42+AD42+AG42+AJ42
AG43: =161491188.56-AG29
B44: COSTOS DE PRODUCCION | C44: =+C45+C60+C78 | F44: =+F45+F60+F78 | H44: =F44/F$13 | I44: =+I45+I60+I78 | K44: =I44/I$13 | L44: =+L45+L60+L78 | N44: =L44/L$13 | O44: =+O45+O60+O78 | Q44: =O44/O$13 | R44: =+R45+R60+R78 | T44: =R44/R$13 | U44: =+U45+U60+U78 | W44: =U44/U$13 | X44: =+X45+X60+X78 | Z44: =X44/X$13 | AA44: =+AA45+AA60+AA78 | AC44: =AA44/AA$13 | AD44: =+AD45+AD60+AD78 | AF44: =AD44/AD$13 | AG44: =+AG45+AG60+AG78 | AI44: =AG44/AG$13 | AJ44: =+AJ45+AJ60+AJ78 | AM44: =C44+F44+I44+L44+O44+R44+U44+X44+AA44+AD44+AG44+AJ44 | AO44: =AM44/AM$13
...

Sheet BUGA
B2: CORPORACIÓN HACIA UN VALLE SOLIDARIO | C2: PYG BUGA 2026
B3: DIAS DE ATENCIÓN | C3: 10 | F3: 20 | I3: 19 | L3: 19 | O3: 19 | R3: 18 | U3: 9 | X3: 19 | AA3: 22 | AD3: 16 | AG3: 18 | AM3: =SUM(C3:AL3)
C4: ENE | D4: x racion | E4: % | F4: FEB | G4: x racion | H4: % | I4: MAR | J4: x racion | K4: % | L4: ABR | M4: x racion | N4: % | O4: MAY | P4: x racion | Q4: % | R4: JUN | S4: x racion | T4: % | U4: JUL | V4: x racion | W4: % | X4: AGO | Y4: x racion | Z4: % | AA4: SEP | AB4: x racion | AC4: % | AD4: OCT | AE4: x racion | AF4: % | AG4: NOV | AI4: % | AJ4: DIC | AK4: x racion | AL4: % | AM4: ACUMULADO | AN4: x racion | AO4: %
B5: COMPLEMENTO INDUSTRIALIZADO (Rac) | AM5: =C5+F5+I5+L5+O5+R5+U5+X5+AA5+AD5+AG5+AJ5 | AO5: =AM5/AM12
B6: COMPLEMENTO PREPARADO (Rac) | AM6: =C6+F6+I6+L6+O6+R6+U6+X6+AA6+AD6+AG6+AJ6 | AO6: =AM6/AM12
B7: ALMUERZO JORNADA UNICA (Rac) | AM7: =C7+F7+I7+L7+O7+R7+U7+X7+AA7+AD7+AG7+AJ7 | AO7: =AM7/AM12
B8: NOVEDADES (Rac) | AM8: =C8+F8+I8+L8+O8+R8+U8+X8+AA8+AD8+AG8+AJ8
AM9: =C9+F9+I9+L9+O9+R9+U9+X9+AA9+AD9+AG9+AJ9
AM10: =C10+F10+I10+L10+O10+R10+U10+X10+AA10+AD10+AG10+AJ10
AM11: =C11+F11+I11+L11+O11+R11+U11+X11+AA11+AD11+AG11+AJ11
B12: TOTAL RACIONES | C12: =SUM(C5:C11) | F12: =SUM(F5:F11) | I12: =SUM(I5:I11) | L12: =SUM(L5:L11) | O12: =SUM(O5:O11) | R12: =SUM(R5:R11) | U12: =SUM(U5:U11) | X12: =SUM(X5:X11) | AA12: =SUM(AA5:AA11) | AD12: =SUM(AD5:AD11) | AG12: =SUM(AG5:AG11) | AJ12: =SUM(AJ5:AJ11) | AM12: =C12+F12+I12+L12+O12+R12+U12+X12+AA12+AD12+AG12+AJ12
B13: INGRESOS BRUTOS | C13: =C14+C23 | F13: =F14+F23 | I13: =I14+I23 | L13: =L14+L23 | O13: =O14+O23 | R13: =R14+R23 | U13: =U14+U23 | X13: =X14+X23 | AA13: =AA14+AA23 | AD13: =AD14+AD23 | AG13: =AG14+AG23 | AJ13: =AJ14+AJ23 | AM13: =C13+F13+I13+L13+O13+R13+U13+X13+AA13+AD13+AG13+AJ13
B14: OPERACIONALES | C14: =C15 | F14: =F15 | I14: =I15 | L14: =L15 | O14: =O15 | R14: =R15 | U14: =U15 | X14: =X15 | AA14: =AA15 | AD14: =AD15 | AG14: =AG15 | AJ14: =AJ15 | AM14: =C14+F14+I14+L14+O14+R14+U14+X14+AA14+AD14+AG14+AJ14
B15: INDUSTRIAS MANUFACTURERAS | C15: =SUM(C16:C22) | F15: =SUM(F16:F22) | I15: =SUM(I16:I22) | L15: =SUM(L16:L22) | O15: =SUM(O16:O22) | R15: =SUM(R16:R22) | U15: =SUM(U16:U22) | X15: =SUM(X16:X22) | AA15: =SUM(AA16:AA22) | AD15: =SUM(AD16:AD22) | AG15: =SUM(AG16:AG22) | AJ15: =SUM(AJ16:AJ22) | AM15: =C15+F15+I15+L15+O15+R15+U15+X15+AA15+AD15+AG15+AJ15 | AO15: =AM15/AM15
B16: COMPLEMENTO INDUSTRIALIZADO (Fac) | D16: =C16/C5 | G16: =F16/F5 | AM16: =C16+F16+I16+L16+O16+R16+U16+X16+AA16+AD16+AG16+AJ16
B17: COMPLEMENTO PREPARADO (Fac) | D17: =C17/C6 | G17: =F17/F6 | AM17: =C17+F17+I17+L17+O17+R17+U17+X17+AA17+AD17+AG17+AJ17 | AN17: =AM17/AM6 | AO17: =AM17/AM$13
B18: ALMUERZO JORNADA UNICA (Fac) | D18: =C18/C7 | G18: =F18/F7 | AM18: =C18+F18+I18+L18+O18+R18+U18+X18+AA18+AD18+AG18+AJ18 | AN18: =AM18/AM7 | AO18: =AM18/AM$13
AM19: =C19+F19+I19+L19+O19+R19+U19+X19+AA19+AD19+AG19+AJ19
B20: NOVEDADES (Fac) | AM20: =C20+F20+I20+L20+O20+R20+U20+X20+AA20+AD20+AG20+AJ20
AM21: =C21+F21+I21+L21+O21+R21+U21+X21+AA21+AD21+AG21+AJ21
AM22: =C22+F22+I22+L22+O22+R22+U22+X22+AA22+AD22+AG22+AJ22
B23: NO OPERACIONALES | C23: =C24 | F23: =F24 | I23: =I24 | L23: =L24 | O23: =O24 | R23: =R24 | U23: =U24 | X23: =X24 | AA23: =AA24 | AM23: =C23+F23+I23+L23+O23+R23+U23+X23+AA23+AD23+AG23+AJ23
B24: FINANCIEROS | C24: =SUM(C25:C27) | F24: =SUM(F25:F27) | I24: =SUM(I25:I27) | L24: =SUM(L25:L27) | O24: =SUM(O25:O27) | R24: =SUM(R25:R27) | U24: =SUM(U25:U27) | X24: =SUM(X25:X27) | AA24: =SUM(AA25:AA27) | AD24: =SUM(AD25:AD27) | AG24: =SUM(AG25:AG27) | AJ24: =SUM(AJ25:AJ27) | AM24: =C24+F24+I24+L24+O24+R24+U24+X24+AA24+AD24+AG24+AJ24
B25: Intereses | AM25: =C25+F25+I25+L25+O25+R25+U25+X25+AA25+AD25+AG25+AJ25
B26: Descuentos Comerciales | AM26: =C26+F26+I26+L26+O26+R26+U26+X26+AA26+AD26+AG26+AJ26
B27: otros Fin | AM27: =C27+F27+I27+L27+O27+R27+U27+X27+AA27+AD27+AG27+AJ27
B28: DESCUENTOS - GASTO OPERACIONAL | C28: =+C29 | F28: =+F29 | I28: =+I29 | L28: =+L29 | O28: =+O29 | R28: =+R29 | U28: =+U29 | X28: =+X29 | AA28: =+AA29 | AD28: =+AD29 | AG28: =+AG29 | AJ28: =+AJ29 | AM28: =C28+F28+I28+L28+O28+R28+U28+X28+AA28+AD28+AG28+AJ28
B29: OTROS | C29: =SUM(C30:C41) | E29: =C29/C13 | F29: =SUM(F30:F37) | H29: =F29/F13 | I29: =SUM(I30:I37) | K29: =I29/I13 | L29: =SUM(L30:L37) | N29: =L29/L13 | O29: =SUM(O30:O37) | R29: =SUM(R30:R37) | T29: =R29/R13 | U29: =SUM(U30:U37) | W29: =U29/U13 | X29: =SUM(X30:X37) | Z29: =X29/X13 | AA29: =SUM(AA30:AA37) | AC29: =AA29/AA13 | AD29: =SUM(AD30:AD37) | AF29: =AD29/AD13 | AG29: =SUM(AG30:AG39) | AI29: =AG29/AG13 | AJ29: =SUM(AJ30:AJ38) | AM29: =C29+F29+I29+L29+O29+R29+U29+X29+AA29+AD29+AG29+AJ29 | AO29: =AM29/AM13
B30: 1% Estampilla Prohospital | C30: =C13*1% | F30: =F13*1% | I30: =I13*1% | L30: =L13*1% | O30: =O13*1% | R30: =R13*1% | U30: =U13*1% | X30: =X13*1% | AA30: =AA13*1% | AD30: =AD13*1% | AG30: =AG13*1% | AJ30: =AJ13*1% | AM30: =C30+F30+I30+L30+O30+R30+U30+X30+AA30+AD30+AG30+AJ30
B31: 2,5% Estampilla Pro Deporte | C31: =C$13*2.5% | F31: =F$13*2.5% | I31: =I$13*2.5% | L31: =L$13*2.5% | O31: =O$13*2.5% | R31: =R$13*2.5% | U31: =U$13*2.5% | X31: =X$13*2.5% | AA31: =AA$13*2.5% | AD31: =AD$13*2.5% | AG31: =AG$13*2.5% | AJ31: =AJ$13*2.5% | AM31: =C31+F31+I31+L31+O31+R31+U31+X31+AA31+AD31+AG31+AJ31
B32: 1% Estampilla Pro Univalle | C32: =C$13*1% | F32: =F$13*1% | I32: =I$13*1% | L32: =L$13*1% | O32: =O$13*1% | R32: =R$13*1% | U32: =U$13*1% | X32: =X$13*1% | AA32: =AA$13*1% | AD32: =AD$13*1% | AG32: =AG$13*1% | AJ32: =AJ$13*1% | AM32: =C32+F32+I32+L32+O32+R32+U32+X32+AA32+AD32+AG32+AJ32
B33: 3% Estampilla Adulto Mayor | C33: =C13*3% | F33: =F13*3% | I33: =I13*3% | L33: =L13*3% | O33: =O13*3% | R33: =R13*3% | U33: =U13*3% | X33: =X13*3% | AA33: =AA13*3% | AD33: =AD13*3% | AG33: =AG13*3% | AJ33: =AJ13*3% | AM33: =C33+F33+I33+L33+O33+R33+U33+X33+AA33+AD33+AG33+AJ33
B34: 0,5% Estampilla Universidad del Pacifico | C34: =C$13*0.5% | F34: =F$13*0.5% | I34: =I$13*0.5% | L34: =L$13*0.5% | O34: =O$13*0.5% | R34: =R$13*0.5% | U34: =U$13*0.5% | X34: =X$13*0.5% | AA34: =AA$13*0.5% | AD34: =AD$13*0.5% | AG34: =AG$13*0.5% | AJ34: =AJ$13*0.5% | AM34: =C34+F34+I34+L34+O34+R34+U34+X34+AA34+AD34+AG34+AJ34
B35: 0,66% Rete Ica | C35: =C$13*0.66% | F35: =F$13*0.66% | I35: =I$13*0.66% | L35: =L$13*0.66% | O35: =O$13*0.66% | R35: =R$13*0.66% | U35: =U$13*0.66% | X35: =X$13*0.66% | AA35: =AA$13*0.66% | AD35: =AD$13*0.66% | AG35: =AG$13*0.66% | AJ35: =AJ$13*0.66% | AM35: =C35+F35+I35+L35+O35+R35+U35+X35+AA35+AD35+AG35+AJ35
B36: Retefuente | C36: =(C$13*1%)*3.5% | F36: =(F$13*1%)*3.5% | I36: =(I$13*1%)*3.5% | L36: =(L$13*1%)*3.5% | O36: =(O$13*1%)*3.5% | R36: =(R$13*1%)*3.5% | U36: =(U$13*1%)*3.5% | X36: =(X$13*1%)*3.5% | AA36: =(AA$13*1%)*3.5% | AD36: =(AD$13*1%)*3.5% | AG36: =(AG$13*1%)*3.5% | AJ36: =(AJ$13*1%)*3.5% | AM36: =C36+F36+I36+L36+O36+R36+U36+X36+AA36+AD36+AG36+AJ36
B37: 2% Juzgado de Familia | C37: =C$13*2% | F37: =F$13*2% | I37: =I$13*2% | L37: =L$13*2% | O37: =O$13*2% | R37: =R$13*2% | U37: =U$13*2% | X37: =X$13*2% | AA37: =AA$13*2% | AD37: =AD$13*2% | AG37: =AG$13*2% | AJ37: =AJ$13*2% | AM37: =C37+F37+I37+L37+O37+R37+U37+X37+AA37+AD37+AG37+AJ37
B38: 0,5% Impuesto de Timbre | AM38: =C38+F38+I38+L38+O38+R38+U38+X38+AA38+AD38+AG38+AJ38
B42: TOTAL INGRESOS NETOS | C42: =+C14+C23-C28 | F42: =+F14+F23-F28 | I42: =+I14+I23-I28 | L42: =+L14+L23-L28 | O42: =+O14+O23-O28 | R42: =+R14+R23-R28 | U42: =+U14+U23-U28 | X42: =+X14+X23-X28 | AA42: =+AA14+AA23-AA28 | AD42: =+AD14+AD23-AD28 | AG42: =+AG14+AG23-AG28 | AJ42: =+AJ14+AJ23-AJ28 | AM42: =C42+F42+I42+L42+O42+R42+U42+X42+AA42+AD42+AG42+AJ42
E43: =(C46+C61)/C13 | H43: =(F46+F61)/F13 | K43: =(I46+I61)/I13 | N43: =(L46+L61)/L13 | Q43: =(O46+O61)/O13 | T43: =(R46+R61)/R13 | W43: =(U46+U61)/U13 | Z43: =(X46+X61)/X13 | AC43: =(AA46+AA61)/AA13 | AF43: =(AD46+AD61)/AD13 | AI43: =(AG46+AG61)/AG13 | AO43: =(AM46+AM61)/AM13
B44: COSTOS DE PRODUCCION | C44: =+C45+C60+C78 | E44: =C44/C$13 | F44: =+F45+F60+F78 | H44: =F44/F$13 | I44: =+I45+I60+I78 | K44: =I44/I$13 | L44: =+L45+L60+L78 | N44: =L44/L$13 | O44: =+O45+O60+O78 | R44: =+R45+R60+R78 | T44: =R44/R$13 | U44: =+U45+U60+U78 | W44: =U44/U$13 | X44: =+X45+X60+X78 | Z44: =X44/X$13 | AA44: =+AA45+AA60+AA78 | AC44: =AA44/AA$13 | AD44: =+AD45+AD60+AD78 | AF44: =AD44/AD$13 | AG44: =+AG45+AG60+AG78 | AI44: =AG44/AG$13 | AJ44: =+AJ45+AJ60+AJ78 | AM44: =C44+F44+I44+L44+O44+R44+U44+X44+AA44+AD44+AG44+AJ44 | AO44: =AM44/AM$13
...

Sheet IMDERTY
B2: CORPORACIÓN HACIA UN VALLE SOLIDARIO | C2: PRESUPUESTO IMDERTY 2024
B3: DIAS DE ATENCIÓN | L3: 20 | O3: 20 | R3: 20 | U3: 20 | X3: 20 | AA3: 20 | AD3: 20 | AG3: 20 | AJ3: 20 | AM3: =SUM(C3:AL3)
